Workbook

Sheet Spell Effects
A1: effect id | B1: name | C1: animation (0) | D1: animation file (0) | E1: spell display (0) | F1: target type (Target) | G1: target size | H1: effected | I1: min lvl effected (1) | J1: max lvl effected (50) | K1: effect type | L1: duration | M1: attack animation (0) | N1: cast animation (1) | O1: spell damage works (0) | P1: energy type (0) | Q1: hp formula (0) | R1: mp formula (0) | S1: sp_formula (0) | T1: hp (0) | U1: mp (0) | V1: sp (0) | W1: ac (0) | X1: str (0) | Y1: sta (0) | Z1: dex (0) | AA1: int (0) | AB1: fr (0) | AC1: wr (0) | AD1: sr (0) | AE1: ar (0) | AF1: er (0) | AG1: hp % reg | AH1: hp static reg | AI1: mp % reg | AJ1: mp static reg | AK1: haste | AL1: sd | AM1: sc | AN1: melee d | AO1: melee c | AP1: dmg reduce | AQ1: move speed increase % | AR1: body id | AS1: oneffect text | AT1: offeffect text | AU1: face id | AV1: hair id | AW1: hair r | AX1: hair g | AY1: hair b | AZ1: hair a | BA1: body r | BB1: body g | BC1: body b | BD1: body a | BE1: tele map | BF1: tele x | BG1: tele y | BH1: taunt aggro | BI1: works in pvp (1) | BJ1: works not in pvp (0) | BK1: buff removable (1) | BL1: buff graphic | BM1: buff graphic file | BN1: buff doesnt stack over | BO1: buff stacks over | BP1: random join chance | BQ1: on hit spell effect id | BR1: on hit spell chance | BS1: on attack spell effect id | BT1: on attack spell chance | BU1: snare % | BV1: only hits one npc (0) | BW1: script path | BX1: script params
A2: 1 | B2: Small Health Potion | H2: Self | K2: 0 | Q2: 25 | BJ2: 1
A3: 2 | B3: Small Mana Potion | H3: Self | K3: 0 | R3: 25 | BJ3: 1
A4: 3 | B4: Healing 1 | C4: 815015 | H4: SelfPlayer | K4: 0 | O4: 1 | Q4: 25 | BJ4: 1
A5: 4 | B5: Fortify 1 | C5: 815016 | H5: SelfPlayer | K5: 1 | L5: 600 | T5: 50 | W5: 20 | BJ5: 1 | BL5: 810018 | BM5: 20107 | BN5: 39 40 41 42
A6: 5 | B6: Backstab 1 | C6: 815010 | F6: LineFront | G6: 1 | H6: NPCPlayer | K6: 0 | M6: 1 | O6: 1 | Q6: -2 * (%cstr + %cwdmg + %clevel)
A7: 6 | B7: Taunt 1 | C7: 815014 | H7: NPC | K7: 0 | Q7: -1 | BH7: 1000
A8: 7 | B8: Elemental Strike 1 | C8: 815000 | H8: NPCPlayer | K8: 0 | O8: 1 | Q8: -10
A9: 8 | B9: Elemental Strike 2 | C9: 815003 | H9: NPCPlayer | K9: 0 | O9: 1 | Q9: -20
A10: 9 | B10: Arcane Shield 1 | C10: 815016 | H10: SelfPlayer | K10: 1 | L10: 600 | W10: 10 | BJ10: 1 | BL10: 810018 | BM10: 20107 | BN10: 101 113 109 112
A11: 10 | B11: Elemental Strike 3 | C11: 815001 | H11: NPCPlayer | K11: 0 | O11: 1 | Q11: -40
A12: 11 | B12: Elemental Shielding 1 | C12: 815023 | H12: SelfPlayer | K12: 14 | L12: 600 | BJ12: 1 | BL12: 810004 | BM12: 20107 | BN12: 104 | BQ12: 63
A13: 12 | B13: Teleportation | C13: 815012 | H13: SelfPlayer | K13: 5 | BJ13: 1
A14: 13 | B14: Root | C14: 815038 | H14: NPC | K14: 8 | L14: 25 | BK14: 0 | BL14: 810024 | BM14: 20107
A15: 14 | B15: Elemental Strike 4 | C15: 815002 | H15: NPCPlayer | K15: 0 | O15: 1 | Q15: -60
A16: 15 | B16: Snare | C16: 815034 | H16: NPC | K16: 9 | L16: 30 | BK16: 0 | BU16: 80
A17: 16 | B17: Elemental Strike 5 | C17: 815000 | E17: Tile | F17: Random | G17: 4 | H17: NPCPlayer | K17: 0 | O17: 1 | Q17: -80 | BP17: 33
A18: 17 | B18: Gate | C18: 815012 | H18: Self | K18: 5 | BE18: 0
A19: 18 | B19: Regeneration 1 | C19: 815013 | H19: SelfPlayer | K19: 1 | L19: 180 | AG19: 0.02 | BJ19: 1 | BL19: 810008 | BM19: 20107 | BN19: 105 111
A20: 19 | B20: Bind Self | C20: 815014 | H20: Self | K20: 6
A21: 20 | B21: Elemental Strike 6 | C21: 815003 | E21: Tile | F21: Plus | G21: 1 | H21: NPCPlayer | K21: 0 | O21: 1 | Q21: -100
A22: 21 | B22: Rampant Rage | C22: 815048 | H22: Self | K22: 13 | L22: 60 | BL22: 810033 | BM22: 20107 | BN22: 124 | BS22: 60
A23: 22 | B23: Insight | C23: 815014 | H23: Self | K23: 12 | L23: 300 | BL23: 810007 | BM23: 20107
A24: 23 | B24: Area Taunt | C24: 815014 | E24: Tile | F24: Area | G24: 4 | H24: NPC | K24: 0 | O24: 1 | Q24: -10 | BH24: 3000
A25: 24 | B25: Ground Slam 1 | C25: 815001 | E25: Tile | F25: Plus | G25: 1 | H25: NPC | K25: 7 | L25: 10 | O25: 1 | Q25: -30 | BK25: 0 | BL25: 810011 | BM25: 20107
A26: 25 | B26: Berserker 1 | C26: 815024 | H26: Self | K26: 4 | L26: 45 | X26: 50 | AK26: 0.1 | BL26: 810000 | BM26: 20107 | BN26: 121 122
A27: 26 | B27: Poison Weapon 1 | C27: 815041 | H27: Self | K27: 13 | L27: 60 | BL27: 810014 | BM27: 20107 | BN27: 125 | BS27: 61
A28: 27 | B28: Backstab 2 | C28: 815010 | F28: LineFront | G28: 1 | H28: NPCPlayer | K28: 0 | M28: 1 | O28: 1 | Q28: -3 * (%cstr + %cwdmg + %clevel)
A29: 28 | B29: Nimble 1 | C29: 815021 | H29: Self | K29: 1 | L29: 60 | Z29: 50 | AK29: 0.1 | BL29: 810021 | BM29: 20107 | BN29: 127
A30: 29 | B30: Backstab 3 | C30: 815010 | F30: LineFront | G30: 1 | H30: NPCPlayer | K30: 0 | M30: 1 | O30: 1 | Q30: -4 * (%cstr + %cwdmg + %clevel)
A31: 30 | B31: Illusion: Snowman | C31: 815014 | H31: SelfPlayer | K31: 1 | L31: 300 | AR31: 114 | BJ31: 1 | BL31: 810007 | BM31: 20107
A32: 31 | B32: Health Potion | H32: Self | K32: 0 | Q32: 50 | BJ32: 1
A33: 32 | B33: Mana Potion | H33: Self | K33: 0 | R33: 50 | BJ33: 1
A34: 33 | B34: Large Health Potion | H34: Self | K34: 0 | Q34: 150 | BJ34: 1
A35: 34 | B35: Large Mana Potion | H35: Self | K35: 0 | R35: 150 | BJ35: 1
A36: 35 | B36: Healing 2 | C36: 815015 | H36: SelfPlayer | K36: 0 | O36: 1 | Q36: 50 | BJ36: 1
A37: 36 | B37: Healing 3 | C37: 815015 | H37: SelfPlayer | K37: 0 | O37: 1 | Q37: 125 | BJ37: 1
A38: 37 | B38: Healing 4 | C38: 815015 | H38: SelfPlayer | K38: 0 | O38: 1 | Q38: 350 | BJ38: 1
A39: 38 | B39: Healing 5 | C39: 815015 | H39: SelfPlayer | K39: 0 | O39: 1 | Q39: 1000 | BJ39: 1
A40: 39 | B40: Fortify 2 | C40: 815016 | H40: SelfPlayer | I40: 5 | K40: 1 | L40: 600 | T40: 100 | W40: 35 | BJ40: 1 | BL40: 810018 | BM40: 20107 | BN40: 40 41 42 | BO40: 4
...

Sheet Spells
A1: spell id | B1: name | C1: description | D1: target | E1: classes (0) | F1: aether ms (100) | G1: spellbook graphic | H1: graphic file | I1: hp cost (0) | J1: hp % cost (0) | K1: mp cost (0) | L1: mp % cost (0) | M1: sp cost (0) | N1: sp % cost (0) | O1: spell effect id | Q1: Spell Effect Name (Don't touch)
A2: 1 | B2: Healing 1 | D2: 0 | E2: 31 | G2: 810006 | H2: 20107 | K2: 5 | O2: 3 | Q2: =LOOKUP(O2, 'Spell Effects'!A:A, 'Spell Effects'!B:B) -> Healing 1
A3: 2 | B3: Fortify 1 | D3: 0 | E3: 31 | F3: 30000 | G3: 810018 | H3: 20107 | K3: 20 | O3: 4 | Q3: =LOOKUP(O3, 'Spell Effects'!A:A, 'Spell Effects'!B:B) -> Fortify 1
A4: 3 | B4: Backstab 1 | D4: 1 | E4: 59 | F4: 18000 | G4: 810000 | H4: 20107 | K4: 20 | O4: 5 | Q4: =LOOKUP(O4, 'Spell Effects'!A:A, 'Spell Effects'!B:B) -> Backstab 1
A5: 4 | B5: Taunt 1 | D5: 0 | E5: 55 | F5: 5000 | G5: 810000 | H5: 20107 | K5: 10 | O5: 6 | Q5: =LOOKUP(O5, 'Spell Effects'!A:A, 'Spell Effects'!B:B) -> Taunt 1
A6: 5 | B6: Elemental Strike 1 | D6: 0 | E6: 47 | F6: 500 | G6: 810012 | H6: 20107 | K6: 5 | O6: 7 | Q6: =LOOKUP(O6, 'Spell Effects'!A:A, 'Spell Effects'!B:B) -> Elemental Strike 1
A7: 6 | B7: Elemental Strike 2 | D7: 0 | E7: 47 | F7: 500 | G7: 810013 | H7: 20107 | K7: 10 | O7: 8 | Q7: =LOOKUP(O7, 'Spell Effects'!A:A, 'Spell Effects'!B:B) -> Elemental Strike 2
A8: 7 | B8: Arcane Shield 1 | D8: 0 | E8: 47 | F8: 10000 | G8: 810018 | H8: 20107 | K8: 20 | O8: 9 | Q8: =LOOKUP(O8, 'Spell Effects'!A:A, 'Spell Effects'!B:B) -> Arcane Shield 1
A9: 8 | B9: Elemental Strike 3 | D9: 0 | E9: 47 | F9: 500 | G9: 810011 | H9: 20107 | K9: 20 | O9: 10 | Q9: =LOOKUP(O9, 'Spell Effects'!A:A, 'Spell Effects'!B:B) -> Elemental Strike 3
A10: 9 | B10: Elemental Shielding 1 | D10: 0 | E10: 47 | F10: 10000 | G10: 810004 | H10: 20107 | K10: 20 | O10: 11 | Q10: =LOOKUP(O10, 'Spell Effects'!A:A, 'Spell Effects'!B:B) -> Elemental Shielding 1
A11: 10 | B11: Teleportation | D11: 1 | E11: 47 | F11: 10000 | G11: 810009 | H11: 20107 | K11: 20 | O11: 12 | Q11: =LOOKUP(O11, 'Spell Effects'!A:A, 'Spell Effects'!B:B) -> Teleportation
A12: 11 | B12: Root | D12: 0 | E12: 15 | G12: 810024 | H12: 20107 | K12: 20 | O12: 13 | Q12: =LOOKUP(O12, 'Spell Effects'!A:A, 'Spell Effects'!B:B) -> Root
A13: 12 | B13: Elemental Strike 4 | D13: 0 | E13: 47 | F13: 500 | G13: 810003 | H13: 20107 | K13: 40 | O13: 14 | Q13: =LOOKUP(O13, 'Spell Effects'!A:A, 'Spell Effects'!B:B) -> Elemental Strike 4
A14: 13 | B14: Snare | D14: 0 | E14: 47 | G14: 810023 | H14: 20107 | K14: 50 | O14: 15 | Q14: =LOOKUP(O14, 'Spell Effects'!A:A, 'Spell Effects'!B:B) -> Snare
A15: 14 | B15: Elemental Strike 5 | D15: 0 | E15: 47 | F15: 1000 | G15: 810012 | H15: 20107 | K15: 80 | O15: 16 | Q15: =LOOKUP(O15, 'Spell Effects'!A:A, 'Spell Effects'!B:B) -> Elemental Strike 5
A16: 15 | B16: Gate | D16: 1 | E16: 15 | F16: 20000 | G16: 810009 | H16: 20107 | K16: 30 | O16: 17 | Q16: =LOOKUP(O16, 'Spell Effects'!A:A, 'Spell Effects'!B:B) -> Gate
A17: 16 | B17: Regeneration 1 | D17: 0 | E17: 47 | F17: 90000 | G17: 810008 | H17: 20107 | K17: 80 | O17: 18 | Q17: =LOOKUP(O17, 'Spell Effects'!A:A, 'Spell Effects'!B:B) -> Regeneration 1
A18: 17 | B18: Bind Self | D18: 1 | E18: 15 | F18: 20000 | G18: 810007 | H18: 20107 | K18: 80 | O18: 19 | Q18: =LOOKUP(O18, 'Spell Effects'!A:A, 'Spell Effects'!B:B) -> Bind Self
A19: 18 | B19: Group Teleportation | D19: 2 | E19: 47 | F19: 120000 | G19: 810009 | H19: 20107 | K19: 100 | O19: 12 | Q19: =LOOKUP(O19, 'Spell Effects'!A:A, 'Spell Effects'!B:B) -> Teleportation
A20: 19 | B20: Elemental Strike 6 | D20: 0 | E20: 47 | F20: 1000 | G20: 810013 | H20: 20107 | K20: 160 | O20: 20 | Q20: =LOOKUP(O20, 'Spell Effects'!A:A, 'Spell Effects'!B:B) -> Elemental Strike 6
A21: 20 | B21: Rampant Rage | D21: 1 | E21: 55 | F21: 120000 | G21: 810033 | H21: 20107 | K21: 30 | O21: 21 | Q21: =LOOKUP(O21, 'Spell Effects'!A:A, 'Spell Effects'!B:B) -> Rampant Rage
A22: 21 | B22: Insight | D22: 1 | E22: 55 | F22: 180000 | G22: 810007 | H22: 20107 | K22: 30 | O22: 22 | Q22: =LOOKUP(O22, 'Spell Effects'!A:A, 'Spell Effects'!B:B) -> Insight
A23: 22 | B23: Area Taunt | D23: 1 | E23: 55 | F23: 10000 | G23: 810000 | H23: 20107 | K23: 40 | O23: 23 | Q23: =LOOKUP(O23, 'Spell Effects'!A:A, 'Spell Effects'!B:B) -> Area Taunt
A24: 23 | B24: Ground Slam 1 | D24: 1 | E24: 55 | F24: 180000 | G24: 810011 | H24: 20107 | K24: 50 | O24: 24 | Q24: =LOOKUP(O24, 'Spell Effects'!A:A, 'Spell Effects'!B:B) -> Ground Slam 1
A25: 24 | B25: Berserker 1 | D25: 1 | E25: 55 | F25: 225000 | G25: 810000 | H25: 20107 | K25: 50 | O25: 25 | Q25: =LOOKUP(O25, 'Spell Effects'!A:A, 'Spell Effects'!B:B) -> Berserker 1
A26: 25 | B26: Poison Weapon 1 | D26: 1 | E26: 59 | F26: 120000 | G26: 810014 | H26: 20107 | K26: 30 | O26: 26 | Q26: =LOOKUP(O26, 'Spell Effects'!A:A, 'Spell Effects'!B:B) -> Poison Weapon 1
... A29: 28 | B29: Backstab 3 | D29: 1 | E29: 59 | F29: 27000 | G29: 810000 | H29: 20107 | K29: 60 | O29: 29 | Q29: =LOOKUP(O29, 'Spell Effects'!A:A, 'Spell Effects'!B:B) -> Backstab 3
A30: 29 | B30: Illusion: Snowman | D30: 0 | F30: 300000 | G30: 810007 | H30: 20107 | K30: 100 | O30: 30 | Q30: =LOOKUP(O30, 'Spell Effects'!A:A, 'Spell Effects'!B:B) -> Illusion: Snowman
A31: 30 | B31: Healing 2 | D31: 0 | E31: 31 | G31: 810006 | H31: 20107 | K31: 10 | O31: 35 | Q31: =LOOKUP(O31, 'Spell Effects'!A:A, 'Spell Effects'!B:B) -> Healing 2
A32: 31 | B32: Healing 3 | D32: 0 | E32: 31 | G32: 810006 | H32: 20107 | K32: 25 | O32: 36 | Q32: =LOOKUP(O32, 'Spell Effects'!A:A, 'Spell Effects'!B:B) -> Healing 3
A33: 32 | B33: Healing 4 | D33: 0 | E33: 31 | G33: 810006 | H33: 20107 | K33: 50 | O33: 37 | Q33: =LOOKUP(O33, 'Spell Effects'!A:A, 'Spell Effects'!B:B) -> Healing 4
A34: 33 | B34: Healing 5 | D34: 0 | E34: 31 | G34: 810006 | H34: 20107 | K34: 100 | O34: 38 | Q34: =LOOKUP(O34, 'Spell Effects'!A:A, 'Spell Effects'!B:B) -> Healing 5
A35: 34 | B35: Fortify 2 | D35: 0 | E35: 31 | F35: 5000 | G35: 810018 | H35: 20107 | K35: 50 | O35: 39 | Q35: =LOOKUP(O35, 'Spell Effects'!A:A, 'Spell Effects'!B:B) -> Fortify 2
A36: 35 | B36: Fortify 3 | D36: 0 | E36: 31 | F36: 5000 | G36: 810018 | H36: 20107 | K36: 100 | O36: 40 | Q36: =LOOKUP(O36, 'Spell Effects'!A:A, 'Spell Effects'!B:B) -> Fortify 3
A37: 36 | B37: Fortify 4 | D37: 0 | E37: 31 | F37: 5000 | G37: 810018 | H37: 20107 | K37: 150 | O37: 41 | Q37: =LOOKUP(O37, 'Spell Effects'!A:A, 'Spell Effects'!B:B) -> Fortify 4
A38: 37 | B38: Fortify 5 | D38: 0 | E38: 31 | F38: 5000 | G38: 810018 | H38: 20107 | K38: 300 | O38: 42 | Q38: =LOOKUP(O38, 'Spell Effects'!A:A, 'Spell Effects'!B:B) -> Fortify 5
A39: 38 | B39: Strength 1 | D39: 0 | E39: 31 | F39: 5000 | G39: 810020 | H39: 20107 | K39: 20 | O39: 43 | Q39: =LOOKUP(O39, 'Spell Effects'!A:A, 'Spell Effects'!B:B) -> Strength 1
A40: 39 | B40: Strength 2 | D40: 0 | E40: 31 | F40: 5000 | G40: 810020 | H40: 20107 | K40: 50 | O40: 44 | Q40: =LOOKUP(O40, 'Spell Effects'!A:A, 'Spell Effects'!B:B) -> Strength 2
A41: 40 | B41: Strength 3 | D41: 0 | E41: 31 | F41: 5000 | G41: 810020 | H41: 20107 | K41: 75 | O41: 45 | Q41: =LOOKUP(O41, 'Spell Effects'!A:A, 'Spell Effects'!B:B) -> Strength 3
A42: 41 | B42: Strength 4 | D42: 0 | E42: 31 | F42: 5000 | G42: 810020 | H42: 20107 | K42: 100 | O42: 46 | Q42: =LOOKUP(O42, 'Spell Effects'!A:A, 'Spell Effects'!B:B) -> Strength 4
...

Sheet Items
A1: id | B1: usetype | C1: name | D1: description | E1: hp (0) | F1: mp (0) | G1: sp (0) | H1: ac (0) | I1: str (0) | J1: sta (0) | K1: dex (0) | L1: int (0) | M1: fr (0) | N1: wr (0) | O1: sr (0) | P1: ar (0) | Q1: er (0) | R1: min exp (0) | S1: min lvl (0) | T1: max exp (0) | U1: max lvl (0) | V1: weap dmg (0) | W1: weap dly (10) | X1: slot (Misc) | Y1: type (None) | Z1: value (0) | AA1: lore (0) | AB1: bop (0) | AC1: boe (0) | AD1: event (0) | AE1: graphic tile | AF1: graphic file | AG1: equip display | AH1: r | AI1: g | AJ1: b | AK1: a | AL1: classes (0) | AM1: stack (1) | AN1: body state (1) | AO1: effect (0) | AP1: effect % (100) | AQ1: learn spell id (0) | AR1: credits (0) | AS1: script path | AT1: script params
A2: 1 | B2: Money | C2: Gold | AE2: 820100 | AF2: 20398
A3: 2 | B3: Armor | C3: Old Rags | H3: 3 | X3: Chest | Y3: Cloth | Z3: 10 | AE3: 332205 | AF3: 2278 | AG3: 2
A4: 3 | B4: Weapon | C4: Stick | V4: 3 | X4: OneHanded | Y4: OneHandedBlunt | Z4: 10 | AE4: 331405 | AF4: 2270 | AG4: 1 | AN4: 4
A5: 4 | B5: OneTime | C5: Small Health Potion | Z5: 50 | AE5: 820115 | AF5: 20398 | AM5: 99 | AO5: 1
A6: 5 | B6: OneTime | C6: Small Mana Potion | Z6: 50 | AE6: 820112 | AF6: 20398 | AM6: 99 | AO6: 2
A7: 6 | B7: Weapon | C7: Tin Can | E7: 5 | I7: 1 | V7: 13 | X7: OneHanded | Y7: OneHandedBlunt | Z7: 120 | AE7: 331350 | AF7: 2269 | AG7: 60 | AN7: 4
A8: 7 | B8: NoUse | C8: Rabbit Fur | Z8: 40 | AE8: 820601 | AF8: 20403 | AM8: 99
A9: 8 | B9: NoUse | C9: Rabbit Pelt | Z9: 80 | AE9: 820604 | AF9: 20403 | AM9: 99
A10: 9 | B10: Armor | C10: Bunny Ears | E10: 20 | F10: 20 | H10: 20 | I10: 3 | X10: Helmet | AE10: 332209 | AF10: 2278 | AG10: 3
A11: 10 | B11: Scroll | C11: Scroll: Healing 1 | S11: 1 | Z11: 100 | AA11: 1 | AE11: 820110 | AF11: 20398 | AL11: 31 | AQ11: 1
A12: 11 | B12: Weapon | C12: Small Hammer | S12: 5 | V12: 12 | X12: OneHanded | Y12: OneHandedBlunt | Z12: 500 | AE12: 820039 | AF12: 20397 | AG12: 5 | AL12: 22 | AN12: 4
A13: 12 | B13: Weapon | C13: Wooden Stave | S13: 5 | V13: 9 | X13: TwoHanded | Y13: TwoHandedBlunt | Z13: 500 | AE13: 820021 | AF13: 20397 | AG13: 13 | AL13: 38 | AN13: 5
A14: 13 | B14: Weapon | C14: Small Dagger | S14: 5 | V14: 12 | X14: OneHanded | Y14: OneHandedPierce | Z14: 500 | AE14: 331379 | AF14: 2269 | AG14: 11 | AL14: 34 | AN14: 4
A15: 14 | B15: Weapon | C15: Small Sword | S15: 5 | V15: 14 | X15: OneHanded | Y15: OneHandedSword | Z15: 500 | AE15: 820015 | AF15: 20397 | AG15: 10 | AL15: 50 | AN15: 4
A16: 15 | B16: Weapon | C16: Stone Hammer | S16: 15 | V16: 15 | X16: OneHanded | Y16: OneHandedBlunt | Z16: 1500 | AE16: 820039 | AF16: 20397 | AG16: 5 | AL16: 22 | AN16: 4
A17: 16 | B17: Weapon | C17: Hardwood Stave | S17: 15 | V17: 15 | X17: TwoHanded | Y17: TwoHandedBlunt | Z17: 1500 | AE17: 820021 | AF17: 20397 | AG17: 13 | AL17: 38 | AN17: 5
A18: 17 | B18: Weapon | C18: Grim Dagger | S18: 15 | V18: 19 | X18: OneHanded | Y18: OneHandedPierce | Z18: 1500 | AE18: 331379 | AF18: 2269 | AG18: 11 | AL18: 34 | AN18: 4
A19: 18 | B19: Weapon | C19: Long Sword | S19: 15 | V19: 24 | X19: OneHanded | Y19: OneHandedSword | Z19: 1500 | AE19: 820015 | AF19: 20397 | AG19: 10 | AL19: 50 | AN19: 4
A20: 19 | B20: NoUse | C20: Sun Flower | Z20: 50 | AE20: 820120 | AF20: 20398
A21: 20 | B21: NoUse | C21: Pile of Crap | Z21: 20 | AE21: 820124 | AF21: 20398 | AM21: 99
A22: 21 | B22: NoUse | C22: Rubber Ducky | Z22: 100 | AE22: 820111 | AF22: 20398
A23: 22 | B23: Scroll | C23: Scroll: Fortify 1 | S23: 6 | Z23: 600 | AA23: 1 | AE23: 820110 | AF23: 20398 | AL23: 31 | AQ23: 2
A24: 23 | B24: Scroll | C24: Scroll: Backstab 1 | S24: 5 | Z24: 100 | AA24: 1 | AE24: 820110 | AF24: 20398 | AL24: 59 | AQ24: 3
A25: 24 | B25: Scroll | C25: Scroll: Taunt | S25: 1 | Z25: 100 | AA25: 1 | AE25: 820110 | AF25: 20398 | AL25: 55 | AQ25: 4
A26: 25 | B26: Scroll | C26: Scroll: Elemental Strike 1 | S26: 1 | Z26: 100 | AA26: 1 | AE26: 820110 | AF26: 20398 | AL26: 47 | AQ26: 5
A27: 26 | B27: Scroll | C27: Scroll: Elemental Strike 2 | S27: 6 | Z27: 600 | AA27: 1 | AE27: 820110 | AF27: 20398 | AL27: 47 | AQ27: 6
A28: 27 | B28: Scroll | C28: Scroll: Arcane Shield 1 | S28: 7 | Z28: 700 | AA28: 1 | AE28: 820110 | AF28: 20398 | AL28: 47 | AQ28: 7
A29: 28 | B29: Scroll | C29: Scroll: Elemental Strike 3 | S29: 11 | Z29: 1100 | AA29: 1 | AE29: 820110 | AF29: 20398 | AL29: 47 | AQ29: 8
A30: 29 | B30: Scroll | C30: Scroll: Elemental Shield 1 | S30: 12 | Z30: 1200 | AA30: 1 | AE30: 820110 | AF30: 20398 | AL30: 47 | AQ30: 9
A31: 30 | B31: Scroll | C31: Scroll: Teleportation | S31: 14 | Z31: 1400 | AA31: 1 | AE31: 820110 | AF31: 20398 | AL31: 47 | AQ31: 10
A32: 31 | B32: Scroll | C32: Scroll: Root | S32: 15 | Z32: 1500 | AA32: 1 | AE32: 820110 | AF32: 20398 | AL32: 15 | AQ32: 11
A33: 32 | B33: Scroll | C33: Scroll: Elemental Strike 4 | S33: 16 | Z33: 1600 | AA33: 1 | AE33: 820110 | AF33: 20398 | AL33: 47 | AQ33: 12
A34: 33 | B34: Scroll | C34: Scroll: Snare | S34: 20 | Z34: 2000 | AA34: 1 | AE34: 820110 | AF34: 20398 | AL34: 47 | AQ34: 13
... A41: 40 | B41: Scroll | C41: Scroll: Rampant Rage | S41: 5 | Z41: 100 | AA41: 1 | AE41: 820110 | AF41: 20398 | AL41: 55 | AQ41: 20
A42: 41 | B42: Weapon | C42: Winter Blade | E42: 5 | K42: 5 | S42: 12 | V42: 26 | X42: OneHanded | Y42: OneHandedPierce | Z42: 500 | AA42: 1 | AE42: 331356 | AF42: 2269 | AG42: 73 | AL42: 51 | AN42: 4
A43: 42 | B43: OneTime | C43: Health Potion | Z43: 150 | AE43: 820116 | AF43: 20398 | AM43: 99 | AO43: 31
A44: 43 | B44: OneTime | C44: Mana Potion | Z44: 150 | AE44: 820113 | AF44: 20398 | AM44: 99 | AO44: 32
A45: 44 | B45: OneTime | C45: Large Health Potion | Z45: 300 | AE45: 820117 | AF45: 20398 | AM45: 99 | AO45: 33
A46: 45 | B46: OneTime | C46: Large Mana Potion | Z46: 300 | AE46: 820114 | AF46: 20398 | AM46: 99 | AO46: 34
...

Sheet NPCs
A1: ID | B1: type (Monster) | C1: name | D1: title | E1: surname | F1: respawn time | G1: facing (3) | H1: lvl (1) | I1: exp (0) | J1: aggro range (0) | K1: attack range (0) | L1: attack speed (2) | M1: move speed (2) | N1: stationary (0) | O1: stunnable (0) | P1: rootable (0) | Q1: slowable (0) | R1: invincible (0) | S1: hp (0) | T1: mp (0) | U1: sp (0) | V1: class id | W1: ac (0) | X1: str (0) | Y1: sta (0) | Z1: dex (0) | AA1: int (0) | AB1: fr (0) | AC1: wr (0) | AD1: sr (0) | AE1: ar (0) | AF1: er (0) | AG1: body state (3) | AH1: body id (1) | AI1: body r | AJ1: body g | AK1: body b | AL1: body a | AM1: face id (0) | AN1: hair id (0) | AO1: hair r | AP1: hair g | AQ1: hair b | AR1: hair a | AS1: equipped items (0,*,0,*,0,*,0,*,0,*,0,*) | AT1: weapon dmg (1) | AU1: armor pierce | AV1: hp % reg | AW1: hp static reg | AX1: mp % reg | AY1: mp static reg | AZ1: alliance | BA1: stuck behaviour (DoNothing) | BB1: stuck timeout (20) | BC1: credit dealer (0) | BD1: quest ids | BE1: script_path | BF1: script params
A2: 1 | B2: 2 | C2: Mouse | F2: 40 | I2: 20 | K2: 1 | L2: 1.5 | V2: 4 | AH2: 10113 | AT2: 4
A3: 2 | B3: 2 | C3: Lamb | F3: 40 | H3: 2 | I3: 40 | K3: 1 | L3: 1.5 | V3: 4 | AH3: 10114 | AT3: 6
A4: 3 | B4: 2 | C4: Fluffy Little Bunny | F4: 30 | H4: 4 | I4: 104 | J4: 1 | K4: 1 | L4: 1.4 | M4: 1.5 | N4: 1 | Q4: 1 | V4: 4 | AH4: 10140 | AT4: 9 | AZ4: 3
A5: 4 | B5: 2 | C5: Rabid Rabbit | F5: 30 | H5: 8 | I5: 186 | J5: 2 | K5: 1 | L5: 1.4 | M5: 1.3 | N5: 1 | Q5: 1 | V5: 4 | AH5: 10141 | AT5: 18 | AZ5: 3 4
A6: 5 | B6: 2 | C6: Cottontail | F6: 1800 | H6: 9 | I6: 250 | J6: 1 | K6: 1 | L6: 1.5 | M6: 1.5 | N6: 1 | Q6: 1 | V6: 2 | AH6: 121 | AT6: 28 | AZ6: 3 4
A7: 6 | B7: 2 | C7: Asp | F7: 30 | H7: 6 | I7: 124 | J7: 1 | K7: 1 | L7: 1.4 | M7: 1.3 | Q7: 1 | V7: 2 | AH7: 123 | AT7: 13 | AZ7: 6
A8: 7 | B8: 2 | C8: Bat | F8: 30 | H8: 12 | I8: 266 | J8: 3 | K8: 1 | L8: 1.4 | M8: 1.5 | Q8: 1 | V8: 2 | AH8: 10100 | AT8: 38 | AZ8: 7
A9: 8 | B9: 2 | C9: Cow | F9: 30 | H9: 21 | I9: 448 | K9: 1 | L9: 1.5 | M9: 1.5 | Q9: 1 | V9: 2 | AH9: 116 | AT9: 90
A10: 9 | B10: 2 | C10: Ram | F10: 30 | H10: 18 | I10: 368 | K10: 1 | L10: 1.5 | M10: 1.5 | Q10: 1 | V10: 2 | AH10: 10104 | AT10: 72
A11: 10 | B11: 2 | C11: Weak Zombie | F11: 30 | H11: 20 | I11: 404 | J11: 2 | K11: 1 | L11: 1.3 | M11: 1.3 | Q11: 1 | V11: 4 | AH11: 169 | AT11: 80 | AZ11: 10
A12: 11 | B12: 2 | C12: Weak Skeleton | F12: 60 | H12: 30 | I12: 609 | J12: 3 | K12: 1 | L12: 1.5 | N12: 1 | P12: 1 | Q12: 1 | V12: 3 | AH12: 10106 | AT12: 150 | AZ12: 11 12 13 14 15 16 17
A13: 12 | B13: 2 | C13: Weak Skeleton | F13: 60 | H13: 30 | I13: 609 | J13: 3 | K13: 1 | L13: 1.5 | P13: 1 | Q13: 1 | V13: 3 | AH13: 10106 | AT13: 150 | AZ13: 11 12 13 14 15 16 17
A14: 13 | B14: 2 | C14: Skeleton | F14: 60 | H14: 35 | I14: 709 | J14: 4 | K14: 1 | L14: 1.5 | N14: 1 | O14: 1 | Q14: 1 | V14: 3 | AH14: 10106 | AT14: 180 | AZ14: 11 12 13 15 16 17
A15: 14 | B15: 2 | C15: Servant of the Dead | F15: 60 | H15: 40 | I15: 809 | J15: 4 | K15: 1 | L15: 1.5 | M15: 1.3 | N15: 1 | Q15: 1 | V15: 3 | AH15: 10125 | AT15: 210 | AZ15: 11 12 13 14 15 16 17
A16: 15 | B16: 2 | C16: Boney | F16: 3600 | H16: 42 | I16: 1000 | J16: 4 | K16: 1 | L16: 1.5 | M16: 1.3 | N16: 1 | Q16: 1 | V16: 3 | AH16: 10125 | AT16: 240 | AZ16: 11 12 13 14 15 16 17
A17: 16 | B17: 2 | C17: Misplaced Spouse | F17: 3600 | H17: 43 | I17: 1100 | J17: 4 | K17: 1 | L17: 1.5 | M17: 1.3 | N17: 1 | Q17: 1 | V17: 3 | AH17: 10125 | AT17: 240 | AZ17: 11 12 13 14 15 16 17
A18: 17 | B18: 2 | C18: Record Keeper | F18: 3600 | H18: 45 | I18: 1200 | J18: 5 | K18: 1 | L18: 1 | M18: 1.3 | N18: 1 | Q18: 1 | V18: 3 | AH18: 10125 | AT18: 270 | AZ18: 11 12 13 14 15 16 17
A19: 18 | B19: 2 | C19: Piglet | F19: 30 | H19: 21 | I19: 400 | J19: 1 | K19: 1 | L19: 1.4 | M19: 1.4 | O19: 1 | P19: 1 | Q19: 1 | V19: 4 | AH19: 109 | AT19: 57 | AZ19: 18 19
A20: 19 | B20: 2 | C20: Flying Piglet | F20: 3600 | H20: 23 | I20: 600 | J20: 3 | K20: 1 | L20: 1.2 | M20: 1.2 | P20: 1 | Q20: 1 | V20: 3 | AH20: 134 | AT20: 72 | AZ20: 18 19
A21: 20 | B21: 2 | C21: Lost Wabbit | F21: 60 | H21: 12 | I21: 246 | J21: 2 | K21: 1 | L21: 1.3 | M21: 1.5 | N21: 1 | Q21: 1 | V21: 4 | AH21: 10139 | AT21: 51 | AZ21: 20 21 22 23
A22: 21 | B22: 2 | C22: Cute Defenseless Stalker | F22: 60 | H22: 15 | I22: 306 | J22: 2 | K22: 1 | L22: 1.3 | M22: 1.5 | N22: 1 | Q22: 1 | V22: 2 | AH22: 10138 | AT22: 58 | AZ22: 20 21 22 23
A23: 22 | B23: 2 | C23: Roger | F23: 3600 | H23: 14 | I23: 356 | J23: 3 | K23: 1 | L23: 1.3 | M23: 1.3 | N23: 1 | Q23: 1 | V23: 3 | AH23: 121 | AT23: 60 | AZ23: 20 21 22 23
A24: 23 | B24: 2 | C24: Leafeater | F24: 3600 | H24: 17 | I24: 406 | J24: 3 | K24: 1 | L24: 1.3 | M24: 1.3 | N24: 1 | Q24: 1 | V24: 3 | AH24: 121 | AT24: 69 | AZ24: 20 21 22 23
A25: 24 | B25: 2 | C25: Pipsqueek | F25: 30 | H25: 12 | I25: 246 | J25: 1 | K25: 1 | L25: 1.4 | M25: 1.4 | O25: 1 | P25: 1 | Q25: 1 | V25: 4 | AH25: 109 | AT25: 57 | AZ25: 24 25
A26: 25 | B26: 2 | C26: Flying Pipsqueek | F26: 3600 | H26: 14 | I26: 400 | J26: 3 | K26: 1 | L26: 1.2 | M26: 1.2 | P26: 1 | Q26: 1 | V26: 3 | AH26: 134 | AT26: 60 | AZ26: 24 25
A27: 26 | B27: 2 | C27: Fire Asp | F27: 30 | H27: 25 | I27: 508 | J27: 1 | K27: 1 | L27: 1.3 | M27: 1.3 | Q27: 1 | V27: 4 | AH27: 10122 | AT27: 96 | AZ27: 26 27 28
A28: 27 | B28: 2 | C28: Naga Warrior | F28: 30 | H28: 28 | I28: 568 | J28: 2 | K28: 1 | L28: 1.5 | M28: 1.3 | P28: 1 | Q28: 1 | V28: 3 | AG28: 4 | AH28: 1 | AM28: 1 | AS28: 15,192,28,40,180,12,148,231,148,160,0,*,0,*,0,*,10,* | AT28: 112 | AZ28: 26 27 28
A29: 28 | B29: 2 | C29: Naga Rogue | F29: 30 | H29: 30 | I29: 608 | J29: 2 | K29: 1 | L29: 1.1 | M29: 1.3 | P29: 1 | Q29: 1 | V29: 2 | AG29: 4 | AH29: 1 | AM29: 1 | AS29: 15,192,28,40,180,12,148,231,148,160,0,*,0,*,0,*,11,* | AT29: 105 | AZ29: 26 27 28
A30: 29 | B30: 2 | C30: Frozen Waste | F30: 60 | H30: 35 | I30: 709 | J30: 2 | K30: 1 | L30: 1.5 | M30: 1.2 | N30: 1 | Q30: 1 | V30: 3 | AH30: 114 | AT30: 126 | AZ30: 29 30 31 32 33
A31: 30 | B31: 2 | C31: Frozen Waste | F31: 60 | H31: 35 | I31: 709 | J31: 2 | K31: 1 | L31: 1.5 | M31: 1.2 | Q31: 1 | V31: 3 | AH31: 114 | AT31: 126 | AZ31: 29 30 31 32 33
A32: 31 | B32: 2 | C32: Iceman | F32: 60 | H32: 30 | I32: 609 | J32: 2 | K32: 1 | L32: 1.5 | M32: 1.4 | N32: 1 | Q32: 1 | V32: 3 | AH32: 114 | AT32: 111 | AZ32: 29 30 31 32 33
A33: 32 | B33: 2 | C33: Iceman | F33: 60 | H33: 30 | I33: 609 | J33: 2 | K33: 1 | L33: 1.5 | M33: 1.3 | Q33: 1 | V33: 3 | AH33: 114 | AT33: 111 | AZ33: 29 30 31 32 33
A34: 33 | B34: 2 | C34: Frosty | F34: 14400 | H34: 45 | I34: 2109 | J34: 6 | K34: 2 | L34: 1 | M34: 1 | N34: 1 | Q34: 1 | S34: 12000 | V34: 3 | AH34: 153 | AT34: 808 | AZ34: 29 30 31 32 33
A35: 34 | B35: 2 | C35: Weak Persecution | F35: 30 | H35: 35 | I35: 708 | J35: 1 | K35: 1 | L35: 1.4 | M35: 1.4 | O35: 1 | Q35: 1 | V35: 2 | AH35: 128 | AT35: 135 | AZ35: 34 35
A36: 35 | B36: 2 | C36: Moldy Persecution | F36: 30 | H36: 40 | I36: 830 | J36: 3 | K36: 1 | L36: 1.4 | M36: 1.4 | O36: 1 | Q36: 1 | V36: 2 | AH36: 128 | AT36: 147 | AZ36: 34 35
A37: 36 | B37: 2 | C37: Private Persecution | F37: 30 | H37: 40 | I37: 809 | J37: 2 | K37: 1 | L37: 1.4 | M37: 1.4 | N37: 1 | O37: 1 | Q37: 1 | V37: 4 | AH37: 128 | AT37: 141 | AZ37: 36 37
A38: 37 | B38: 2 | C38: Sergeant Persecution | F38: 3600 | H38: 45 | I38: 1309 | J38: 2 | K38: 3 | L38: 1.4 | M38: 1.4 | N38: 1 | Q38: 1 | V38: 3 | AH38: 128 | AT38: 665 | AZ38: 36
A39: 38 | B39: 2 | C39: Strong Persecution | F39: 30 | H39: 50 | I39: 1310 | J39: 3 | K39: 3 | L39: 1.3 | M39: 1.3 | N39: 1 | Q39: 1 | S39: 13362 | V39: 3 | AH39: 128 | AT39: 330 | AZ39: 34 35 36 37 38
A40: 39 | B40: 2 | C40: Persecution | F40: 30 | H40: 50 | I40: 909 | J40: 2 | K40: 1 | L40: 1.4 | M40: 1.3 | Q40: 1 | V40: 3 | AH40: 128 | AT40: 165 | AZ40: 39 49
...

Sheet NPC Spawns
A1: npc id | B1: map id | C1: map x | D1: map y | F1: NPC Name (Don't touch) | G1: Map Name (Don't touch)
A2: 1 | B2: 1 | C2: 80 | D2: 35 | F2: =LOOKUP(A2, NPCs!A:A, NPCs!C:C) -> Mouse | G2: =LOOKUP(B2, Maps!A:A, Maps!B:B) -> Minita
A3: 1 | B3: 1 | C3: 85 | D3: 35 | F3: =LOOKUP(A3, NPCs!A:A, NPCs!C:C) -> Mouse | G3: =LOOKUP(B3, Maps!A:A, Maps!B:B) -> Minita
A4: 1 | B4: 1 | C4: 90 | D4: 35 | F4: =LOOKUP(A4, NPCs!A:A, NPCs!C:C) -> Mouse | G4: =LOOKUP(B4, Maps!A:A, Maps!B:B) -> Minita
A5: 1 | B5: 1 | C5: 80 | D5: 40 | F5: =LOOKUP(A5, NPCs!A:A, NPCs!C:C) -> Mouse | G5: =LOOKUP(B5, Maps!A:A, Maps!B:B) -> Minita
A6: 1 | B6: 1 | C6: 85 | D6: 40 | F6: =LOOKUP(A6, NPCs!A:A, NPCs!C:C) -> Mouse | G6: =LOOKUP(B6, Maps!A:A, Maps!B:B) -> Minita
A7: 1 | B7: 1 | C7: 90 | D7: 40 | F7: =LOOKUP(A7, NPCs!A:A, NPCs!C:C) -> Mouse | G7: =LOOKUP(B7, Maps!A:A, Maps!B:B) -> Minita
A8: 1 | B8: 1 | C8: 80 | D8: 50 | F8: =LOOKUP(A8, NPCs!A:A, NPCs!C:C) -> Mouse | G8: =LOOKUP(B8, Maps!A:A, Maps!B:B) -> Minita
A9: 1 | B9: 1 | C9: 85 | D9: 50 | F9: =LOOKUP(A9, NPCs!A:A, NPCs!C:C) -> Mouse | G9: =LOOKUP(B9, Maps!A:A, Maps!B:B) -> Minita
A10: 1 | B10: 1 | C10: 90 | D10: 50 | F10: =LOOKUP(A10, NPCs!A:A, NPCs!C:C) -> Mouse | G10: =LOOKUP(B10, Maps!A:A, Maps!B:B) -> Minita
A11: 1 | B11: 1 | C11: 80 | D11: 53 | F11: =LOOKUP(A11, NPCs!A:A, NPCs!C:C) -> Mouse | G11: =LOOKUP(B11, Maps!A:A, Maps!B:B) -> Minita
A12: 1 | B12: 1 | C12: 85 | D12: 53 | F12: =LOOKUP(A12, NPCs!A:A, NPCs!C:C) -> Mouse | G12: =LOOKUP(B12, Maps!A:A, Maps!B:B) -> Minita
A13: 1 | B13: 1 | C13: 90 | D13: 53 | F13: =LOOKUP(A13, NPCs!A:A, NPCs!C:C) -> Mouse | G13: =LOOKUP(B13, Maps!A:A, Maps!B:B) -> Minita
... A4315: 182 | B4315: 36 | C4315: 96 | D4315: 6 | F4315: =LOOKUP(A4315, NPCs!A:A, NPCs!C:C) -> Alchemy Supplier Guy | G4315: =LOOKUP(B4315, Maps!A:A, Maps!B:B) -> Shops
A4316: 183 | B4316: 36 | C4316: 60 | D4316: 72 | F4316: =VLOOKUP(A7410,NPCs!A:C,3,0) -> #N/A | G4316: =VLOOKUP(B7410,Maps!A:B,2,0) -> #N/A
A4317: 184 | B4317: 36 | C4317: 65 | D4317: 72 | F4317: =VLOOKUP(A7411,NPCs!A:C,3,0) -> #N/A | G4317: =VLOOKUP(B7411,Maps!A:B,2,0) -> #N/A
A4318: 185 | B4318: 1 | C4318: 73 | D4318: 54 | F4318: =VLOOKUP(A7412,NPCs!A:C,3,0) -> #N/A | G4318: =VLOOKUP(B7412,Maps!A:B,2,0) -> #N/A
A4319: 186 | B4319: 1 | C4319: 73 | D4319: 25 | F4319: =VLOOKUP(A7413,NPCs!A:C,3,0) -> #N/A | G4319: =VLOOKUP(B7413,Maps!A:B,2,0) -> #N/A
A4320: 187 | B4320: 16 | C4320: 51 | D4320: 97 | F4320: =VLOOKUP(A7414,NPCs!A:C,3,0) -> #N/A | G4320: =VLOOKUP(B7414,Maps!A:B,2,0) -> #N/A
A4321: 188 | B4321: 16 | C4321: 66 | D4321: 54 | F4321: =VLOOKUP(A7415,NPCs!A:C,3,0) -> #N/A | G4321: =VLOOKUP(B7415,Maps!A:B,2,0) -> #N/A
A4322: 189 | B4322: 8 | C4322: 83 | D4322: 25 | F4322: =VLOOKUP(A7416,NPCs!A:C,3,0) -> #N/A | G4322: =VLOOKUP(B7416,Maps!A:B,2,0) -> #N/A
A4323: 190 | B4323: 2 | C4323: 14 | D4323: 10 | F4323: =VLOOKUP(A7417,NPCs!A:C,3,0) -> #N/A | G4323: =VLOOKUP(B7417,Maps!A:B,2,0) -> #N/A

Sheet NPC Drops
A1: npc id | B1: item id | C1: stack size | D1: droprate | F1: NPC Name (Don't touch) | G1: Item Name (Don't touch)
A2: 1 | B2: 1 | C2: 10 | D2: 10 | F2: =LOOKUP(A2, NPCs!A:A, NPCs!C:C) -> Mouse | G2: =LOOKUP(B2, Items!A:A, Items!C:C) -> Gold
A3: 1 | B3: 2 | C3: 1 | D3: 5 | F3: =LOOKUP(A3, NPCs!A:A, NPCs!C:C) -> Mouse | G3: =LOOKUP(B3, Items!A:A, Items!C:C) -> Old Rags
A4: 1 | B4: 3 | C4: 1 | D4: 5 | F4: =LOOKUP(A4, NPCs!A:A, NPCs!C:C) -> Mouse | G4: =LOOKUP(B4, Items!A:A, Items!C:C) -> Stick
A5: 1 | B5: 4 | C5: 1 | D5: 5 | F5: =LOOKUP(A5, NPCs!A:A, NPCs!C:C) -> Mouse | G5: =LOOKUP(B5, Items!A:A, Items!C:C) -> Small Health Potion
A6: 1 | B6: 5 | C6: 1 | D6: 5 | F6: =LOOKUP(A6, NPCs!A:A, NPCs!C:C) -> Mouse | G6: =LOOKUP(B6, Items!A:A, Items!C:C) -> Small Mana Potion
A7: 2 | B7: 1 | C7: 10 | D7: 10 | F7: =LOOKUP(A7, NPCs!A:A, NPCs!C:C) -> Lamb | G7: =LOOKUP(B7, Items!A:A, Items!C:C) -> Gold
A8: 2 | B8: 2 | C8: 1 | D8: 5 | F8: =LOOKUP(A8, NPCs!A:A, NPCs!C:C) -> Lamb | G8: =LOOKUP(B8, Items!A:A, Items!C:C) -> Old Rags
A9: 2 | B9: 3 | C9: 1 | D9: 5 | F9: =LOOKUP(A9, NPCs!A:A, NPCs!C:C) -> Lamb | G9: =LOOKUP(B9, Items!A:A, Items!C:C) -> Stick
A10: 2 | B10: 4 | C10: 1 | D10: 5 | F10: =LOOKUP(A10, NPCs!A:A, NPCs!C:C) -> Lamb | G10: =LOOKUP(B10, Items!A:A, Items!C:C) -> Small Health Potion
A11: 2 | B11: 5 | C11: 1 | D11: 5 | F11: =LOOKUP(A11, NPCs!A:A, NPCs!C:C) -> Lamb | G11: =LOOKUP(B11, Items!A:A, Items!C:C) -> Small Mana Potion
A12: 3 | B12: 4 | C12: 1 | D12: 5 | F12: =LOOKUP(A12, NPCs!A:A, NPCs!C:C) -> Fluffy Little Bunny | G12: =LOOKUP(B12, Items!A:A, Items!C:C) -> Small Health Potion
A13: 3 | B13: 5 | C13: 1 | D13: 5 | F13: =LOOKUP(A13, NPCs!A:A, NPCs!C:C) -> Fluffy Little Bunny | G13: =LOOKUP(B13, Items!A:A, Items!C:C) -> Small Mana Potion
... A518: 179 | B518: 592 | C518: 1 | D518: 5 | F518: =LOOKUP(A518, NPCs!A:A, NPCs!C:C) -> Rueben | G518: =LOOKUP(B518, Items!A:A, Items!C:C) -> Scroll: Group Ancient Dungeons Teleport

Sheet NPC Vendor Items
A1: npc id | B1: item id | C1: stack size (1) | D1: stats visible (1) | E1: slot number | G1: NPC Name (Don't touch) | H1: Item Name (Don't touch)
A2: 84 | B2: 88 | E2: 1 | G2: =LOOKUP(A2, NPCs!A:A, NPCs!C:C) -> Hair Dye Guy | H2: =LOOKUP(B2, Items!A:A, Items!C:C) -> Hair Dye: Black
A3: 84 | B3: 169 | E3: 2 | G3: =LOOKUP(A3, NPCs!A:A, NPCs!C:C) -> Hair Dye Guy | H3: =LOOKUP(B3, Items!A:A, Items!C:C) -> Hair Dye: Red
A4: 84 | B4: 170 | E4: 3 | G4: =LOOKUP(A4, NPCs!A:A, NPCs!C:C) -> Hair Dye Guy | H4: =LOOKUP(B4, Items!A:A, Items!C:C) -> Hair Dye: Blue
A5: 84 | B5: 171 | E5: 4 | G5: =LOOKUP(A5, NPCs!A:A, NPCs!C:C) -> Hair Dye Guy | H5: =LOOKUP(B5, Items!A:A, Items!C:C) -> Hair Dye: Grey
A6: 84 | B6: 546 | E6: 5 | G6: =LOOKUP(A6, NPCs!A:A, NPCs!C:C) -> Hair Dye Guy | H6: =LOOKUP(B6, Items!A:A, Items!C:C) -> Hair Dye: Green
A7: 84 | B7: 547 | E7: 6 | G7: =LOOKUP(A7, NPCs!A:A, NPCs!C:C) -> Hair Dye Guy | H7: =LOOKUP(B7, Items!A:A, Items!C:C) -> Hair Dye: Blonde
A8: 85 | B8: 172 | E8: 1 | G8: =LOOKUP(A8, NPCs!A:A, NPCs!C:C) -> Hair 1 | H8: =LOOKUP(B8, Items!A:A, Items!C:C) -> Hair Cut: 1
A9: 86 | B9: 173 | E9: 1 | G9: =LOOKUP(A9, NPCs!A:A, NPCs!C:C) -> Hair 2 | H9: =LOOKUP(B9, Items!A:A, Items!C:C) -> Hair Cut: 2
A10: 87 | B10: 174 | E10: 1 | G10: =LOOKUP(A10, NPCs!A:A, NPCs!C:C) -> Hair 3 | H10: =LOOKUP(B10, Items!A:A, Items!C:C) -> Hair Cut: 3
A11: 88 | B11: 175 | E11: 1 | G11: =LOOKUP(A11, NPCs!A:A, NPCs!C:C) -> Hair 4 | H11: =LOOKUP(B11, Items!A:A, Items!C:C) -> Hair Cut: 4
A12: 89 | B12: 176 | E12: 1 | G12: =LOOKUP(A12, NPCs!A:A, NPCs!C:C) -> Hair 5 | H12: =LOOKUP(B12, Items!A:A, Items!C:C) -> Hair Cut: 5
A13: 90 | B13: 177 | E13: 1 | G13: =LOOKUP(A13, NPCs!A:A, NPCs!C:C) -> Hair 6 | H13: =LOOKUP(B13, Items!A:A, Items!C:C) -> Hair Cut: 6
... A217: 182 | B217: 621 | E217: 1 | G217: =LOOKUP(A217, NPCs!A:A, NPCs!C:C) -> Alchemy Supplier Guy | H217: =LOOKUP(B217, Items!A:A, Items!C:C) -> Empty Bottle

Sheet Maps
A1: id | B1: name | C1: filename | D1: min_level (0) | E1: max_level (0) | F1: min_experience (0) | G1: max_experience (0) | H1: pvp_enabled (0) | I1: chat_enabled (1) | J1: auction_enabled (1) | K1: shout_enabled (1) | L1: spells_enabled (1) | M1: bind_enabled (0) | N1: items_enabled (1) | O1: pets_enabled (1) | P1: script path | Q1: script params
A2: 1 | B2: Minita | C2: Map10001.map | M2: 1
A3: 2 | B3: Its the Bat Cave Robin | C3: Map10002.map
A4: 3 | B4: Graveyard | C4: Map10003.map
A5: 4 | B5: Forest Arena | C5: Map10004.map | H5: 1 | O5: 0
A6: 5 | B6: GM Paradise | C6: Map10005.map
A7: 6 | B7: Undead Hallway | C7: Map10006.map
A8: 7 | B8: Slime Kingdom | C8: Map10007.map
A9: 8 | B9: Roadkill Woods | C9: Map10008.map | M9: 1
A10: 9 | B10: Punchys Playhouse | C10: Map10009.map
A11: 10 | B11: Dead Forest | C11: Map10010.map
A12: 11 | B12: Otherlands | C12: Map10011.map
A13: 12 | B13: Mindless Mines | C13: Map10012.map
A14: 13 | B14: Hay and Frays Stronghold | C14: Map10013.map
A15: 14 | B15: Chiisaiyama | C15: Map10014.map
A16: 15 | B16: Battle Fields | C16: Map10015.map | H16: 1 | O16: 0
A17: 16 | B17: Arctic Lands | C17: Map10016.map
A18: 17 | B18: Northern Arctic Lands | C18: Map10017.map
A19: 18 | B19: Frozen Lake | C19: Map10018.map
A20: 19 | B20: Frigid Maze | C20: Map10019.map
A21: 20 | B21: Tower of the Ancients | C21: Map10020.map
A22: 21 | B22: 21 | C22: Map10021.map
A23: 22 | B23: 22 | C23: Map10022.map | H23: 1
A24: 23 | B24: 23 | C24: Map10023.map
A25: 24 | B25: The Ancients Dungeon | C25: Map10024.map | F25: 100000000 | H25: 1 | O25: 0
A26: 25 | B26: Boondocks | C26: Map10025.map
A27: 26 | B27: 26 | C27: Map10026.map
A28: 27 | B28: Nagan Oasis | C28: Map10027.map
A29: 28 | B29: Savage Isle | C29: Map10028.map
A30: 29 | B30: The Ancients Dungeon | C30: Map10029.map | F30: 20000000 | H30: 1 | O30: 0
A31: 30 | B31: Where am I? | C31: Map10030.map
A32: 31 | B32: Event Hall | C32: Map10031.map
A33: 32 | B33: Sorrows Grove | C33: Map10032.map | F33: 10000000
A34: 33 | B34: The Passing | C34: Map10033.map | F34: 60000000
A35: 34 | B35: Winter Heights | C35: Map10034.map | F35: 300000000
A36: 35 | B36: Paradise | C36: Map10035.map
A37: 36 | B37: Shops | C37: Map10036.map
A38: 37 | B38: Marketplace | C38: Map10037.map
A39: 38 | B39: Pumpkin Grove | C39: Map10038.map
A40: 39 | B40: Haunted House | C40: Map10039.map | D40: 40
...

Sheet Map Required Items
A1: map_id | B1: item_template_id
A2: 29 | B2: 266
A3: 43 | B3: 458
A4: 40 | B4: 516

Sheet Combinations
A1: id | B1: name | C1: min level (1) | D1: max level (50) | E1: min experience (0) | F1: max experience (0) | G1: class restrictions (0)
A2: 1 | B2: Cloth
A3: 2 | B3: Cloth
A4: 3 | B4: Cloth
A5: 4 | B5: Cloth
A6: 5 | B6: Cloth
A7: 6 | B7: Cloth
A8: 7 | B8: Cloth Shirt
A9: 8 | B9: Practice Katana
A10: 9 | B10: Soft Belt
A11: 10 | B11: Cat Ears
A12: 11 | B12: Black Cat Ears
A13: 12 | B13: Bonfire
... A73: 72 | B73: Spell Critical Potion

Sheet Combination Item Required
A1: combination id | B1: item template id | D1: Combination Name (Don't touch) | E1: Ingredient Name (don't touch)
A2: 1 | B2: 340 | D2: =LOOKUP(A2, Combinations!A:A, Combinations!B:B) -> Cloth | E2: =LOOKUP(B2, Items!A:A, Items!C:C) -> Needle
A3: 1 | B3: 348 | D3: =LOOKUP(A3, Combinations!A:A, Combinations!B:B) -> Cloth | E3: =LOOKUP(B3, Items!A:A, Items!C:C) -> Spool of Blue Thread
A4: 2 | B4: 340 | D4: =LOOKUP(A4, Combinations!A:A, Combinations!B:B) -> Cloth | E4: =LOOKUP(B4, Items!A:A, Items!C:C) -> Needle
A5: 2 | B5: 349 | D5: =LOOKUP(A5, Combinations!A:A, Combinations!B:B) -> Cloth | E5: =LOOKUP(B5, Items!A:A, Items!C:C) -> Spool of Green Thread
A6: 3 | B6: 340 | D6: =LOOKUP(A6, Combinations!A:A, Combinations!B:B) -> Cloth | E6: =LOOKUP(B6, Items!A:A, Items!C:C) -> Needle
A7: 3 | B7: 350 | D7: =LOOKUP(A7, Combinations!A:A, Combinations!B:B) -> Cloth | E7: =LOOKUP(B7, Items!A:A, Items!C:C) -> Spool of Red Thread
A8: 4 | B8: 340 | D8: =LOOKUP(A8, Combinations!A:A, Combinations!B:B) -> Cloth | E8: =LOOKUP(B8, Items!A:A, Items!C:C) -> Needle
A9: 4 | B9: 351 | D9: =LOOKUP(A9, Combinations!A:A, Combinations!B:B) -> Cloth | E9: =LOOKUP(B9, Items!A:A, Items!C:C) -> Spool of Black Thread
A10: 5 | B10: 340 | D10: =LOOKUP(A10, Combinations!A:A, Combinations!B:B) -> Cloth | E10: =LOOKUP(B10, Items!A:A, Items!C:C) -> Needle
A11: 5 | B11: 352 | D11: =LOOKUP(A11, Combinations!A:A, Combinations!B:B) -> Cloth | E11: =LOOKUP(B11, Items!A:A, Items!C:C) -> Spool of Pink Thread
A12: 6 | B12: 340 | D12: =LOOKUP(A12, Combinations!A:A, Combinations!B:B) -> Cloth | E12: =LOOKUP(B12, Items!A:A, Items!C:C) -> Needle
A13: 6 | B13: 353 | D13: =LOOKUP(A13, Combinations!A:A, Combinations!B:B) -> Cloth | E13: =LOOKUP(B13, Items!A:A, Items!C:C) -> Spool of Purple Thread
... A301: 72 | B301: 627 | D301: =LOOKUP(A301, Combinations!A:A, Combinations!B:B) -> Spell Critical Potion | E301: =LOOKUP(B301, Items!A:A, Items!C:C) -> Orange Droplet

Sheet Combination Item Result
A1: result id | B1: item template id | D1: Combination Name (Don't touch) | E1: Ingredient Name (don't touch)
A2: 1 | B2: 449 | D2: =LOOKUP(A2, Combinations!A:A, Combinations!B:B) -> Cloth | E2: =LOOKUP(B2, Items!A:A, Items!C:C) -> Cloth
A3: 2 | B3: 449 | D3: =LOOKUP(A3, Combinations!A:A, Combinations!B:B) -> Cloth | E3: =LOOKUP(B3, Items!A:A, Items!C:C) -> Cloth
A4: 3 | B4: 449 | D4: =LOOKUP(A4, Combinations!A:A, Combinations!B:B) -> Cloth | E4: =LOOKUP(B4, Items!A:A, Items!C:C) -> Cloth
A5: 4 | B5: 449 | D5: =LOOKUP(A5, Combinations!A:A, Combinations!B:B) -> Cloth | E5: =LOOKUP(B5, Items!A:A, Items!C:C) -> Cloth
A6: 5 | B6: 449 | D6: =LOOKUP(A6, Combinations!A:A, Combinations!B:B) -> Cloth | E6: =LOOKUP(B6, Items!A:A, Items!C:C) -> Cloth
A7: 6 | B7: 449 | D7: =LOOKUP(A7, Combinations!A:A, Combinations!B:B) -> Cloth | E7: =LOOKUP(B7, Items!A:A, Items!C:C) -> Cloth
A8: 7 | B8: 450 | D8: =LOOKUP(A8, Combinations!A:A, Combinations!B:B) -> Cloth Shirt | E8: =LOOKUP(B8, Items!A:A, Items!C:C) -> Cloth Shirt
A9: 8 | B9: 451 | D9: =LOOKUP(A9, Combinations!A:A, Combinations!B:B) -> Practice Katana | E9: =LOOKUP(B9, Items!A:A, Items!C:C) -> Practice Katana
A10: 9 | B10: 452 | D10: =LOOKUP(A10, Combinations!A:A, Combinations!B:B) -> Soft Belt | E10: =LOOKUP(B10, Items!A:A, Items!C:C) -> Soft Belt
A11: 10 | B11: 453 | D11: =LOOKUP(A11, Combinations!A:A, Combinations!B:B) -> Cat Ears | E11: =LOOKUP(B11, Items!A:A, Items!C:C) -> Cat Ears
A12: 11 | B12: 454 | D12: =LOOKUP(A12, Combinations!A:A, Combinations!B:B) -> Black Cat Ears | E12: =LOOKUP(B12, Items!A:A, Items!C:C) -> Black Cat Ears
A13: 12 | B13: 331 | D13: =LOOKUP(A13, Combinations!A:A, Combinations!B:B) -> Bonfire | E13: =LOOKUP(B13, Items!A:A, Items!C:C) -> Bonfire
... A73: 72 | B73: 632 | D73: =LOOKUP(A73, Combinations!A:A, Combinations!B:B) -> Spell Critical Potion | E73: =LOOKUP(B73, Items!A:A, Items!C:C) -> Spell Critical Potion

Sheet Warptiles
A1: map id | B1: map x | C1: map y | D1: warp to map id | E1: warp to x | F1: warp to y
A2: 4 | B2: 25 | C2: 14 | D2: 1 | E2: 42 | F2: 28
A3: 1 | B3: 42 | C3: 27 | D3: 4 | E3: 24 | F3: 14
A4: 4 | B4: 25 | C4: 15 | D4: 1 | E4: 41 | F4: 28
A5: 1 | B5: 41 | C5: 27 | D5: 4 | E5: 24 | F5: 15
A6: 1 | B6: 40 | C6: 27 | D6: 4 | E6: 24 | F6: 15
A7: 15 | B7: 13 | C7: 15 | D7: 1 | E7: 39 | F7: 28
A8: 15 | B8: 12 | C8: 15 | D8: 1 | E8: 39 | F8: 28
A9: 15 | B9: 11 | C9: 15 | D9: 1 | E9: 38 | F9: 28
A10: 15 | B10: 10 | C10: 15 | D10: 1 | E10: 37 | F10: 28
A11: 15 | B11: 9 | C11: 15 | D11: 1 | E11: 37 | F11: 28
A12: 1 | B12: 37 | C12: 27 | D12: 15 | E12: 9 | F12: 14
A13: 1 | B13: 38 | C13: 27 | D13: 15 | E13: 11 | F13: 14
... A346: 40 | B346: 17 | C346: 98 | D346: 29 | E346: 60 | F346: 48

Sheet Quests
A1: id | B1: name | C1: description | D1: pass text | E1: fail text | F1: classes (0) | G1: min experience required (0) | H1: max experience required (0) | I1: min level required (0) | J1: max level required (0) | K1: repeatable (0) | L1: show progress (0) | M1: only one player can complete (0) | N1: prerequisite quest ids
A2: 1 | B2: Path of the Warrior | C2: Hey there, if you're looking to follow the\npath of the warrior, I can make you one.\n\nWarriors rely on their HP and strength,\ntanking for the party.\n\nIf raw power and high health interests\nyou, then speak with me. | D2: I have transformed you into a warrior.\nI have given you some items to help you\nalong your journey. Make me proud. | E2: You do not meet the requirements. | F2: 253 | I2: 5 | J2: 5 | K2: 1 | L2: 1
A3: 2 | B3: Path of the Magus | C3: Hey there, if you're looking to follow the\npath of the Magus, I can make you one.\n\nMagus rely on their MP and intelligence,\ndoing high damage from a range.\n\nIf high damage with safety and utility\ninterests you, then speak with me. | D3: I have transformed you into a Magus.\nI have given you some items to help you\nalong your journey. Make me proud. | E3: You do not meet the requirements. | F3: 253 | I3: 5 | J3: 5 | K3: 1 | L3: 1
A4: 3 | B4: Path of the Rogue | C4: Hey there, if you're looking to follow the\npath of the Rogue, I can make you one.\n\nRogues rely on doing high damage using a\ncombination of HP and MP and critical\nstrikes.\n\nIf the path of the Rogue interests you,\nthen speak with me. | D4: I have transformed you into a Rogue.\nI have given you some items to help you\nalong your journey. Make me proud. | E4: You do not meet the requirements. | F4: 253 | I4: 5 | J4: 5 | K4: 1 | L4: 1
A5: 4 | B5: Path of the Priest | C5: Hey there, if you're looking to follow the\npath of the Priest, I can make you one.\n\nPriests are vital to the survival of a\nparty. They heal and provide buffs.\n\nIf the path of the Priest interests you,\nthen speak with me. | D5: I have transformed you into a Priest.\nI have given you some items to help you\nalong your journey. Make me proud. | E5: You do not meet the requirements. | F5: 253 | I5: 5 | J5: 5 | K5: 1 | L5: 1
A6: 5 | B6: Mouse Killer | C6: Hello there, adventurer. These mice are\ngetting into everything and eating our\ncrops.\n\nHelp me kill 15 of these darn mice and I\nwill reward you. | D6: Thank you for eliminating those pesky\nmice. Take these potions and gold. | E6: You do not meet the requirements. | I6: 1 | L6: 1
A7: 6 | B7: Sheep Wool | C7: Hello! These sheep are getting out of\nhand, there are too many of them and I\nneed their wool.\n\nPlease lend a hand and bring me 10 wool.\nYou will be rewarded. | D7: Phew! That was hard work. Thank you.\nTake this as payment. | E7: You do not meet the requirements. | I7: 2
A8: 7 | B8: Jack's Jacket | C8: Hi there! Brrr. It's cold out here. Please\nbring me 10 rabbit pelts and 10 rabbit fur\nso that I can make a jacket.\n\nBy the way, my friend Jill is out here\nsomewhere. I don't know where she went.\nLet me know where she is so I know she's\nalright. | D8: Much better! Glad to know Jill is alright.\nHere, take these pants. | E8: You do not meet the requirements. | I8: 5 | L8: 1
A9: 8 | B9: Angry Rabbits | C9: Helppppp! These bunnies are staring at me\nlike they want to kill me. I'm scared.\nPlease kill 20 of them so I get out of\nhere. | D9: Thank you so much! Now I can go and see\nJack! | E9: You do not meet the requirements. | I9: 5 | L9: 1
A10: 9 | B10: Biting Asps | C10: I keep stepping on these damn Asps and\nget bitten by them. Wipe them out. Kill\n20 Asps and you will be rewarded. | D10: You squashed those Asps. Thank you. | E10: You do not meet the requirements. | I10: 7 | L10: 1
A11: 10 | B11: Screeching Bats | C11: Hello there! These bats are driving me\ncrazy with their constant screeching.\nKill 25 of them for me, would you? | D11: Muchhhh better! I can finally hear my own\nthoughts. Here take this. | E11: You do not meet the requirements. | I11: 10 | L11: 1

Sheet Quest Reqs
A1: id | B1: quest id | C1: requirement type | D1: value | E1: value2 | F1: keep requirement? (0) | H1: Quest (Don't touch) | I1: Requirement Name (Don't touch)
A2: 1 | B2: 5 | C2: Kill | D2: 1 | E2: 15 | H2: =VLOOKUP(B2,Quests!A:C,2,0) -> Mouse Killer | I2: =IF(C2 = "Item", VLOOKUP(D2,Items!A:C,3,0), IF(OR(C2 = "Kill", C2 = "TalkToNPC"), VLOOKUP(D2,NPCs!A:C,3,0), "")) -> Mouse
A3: 2 | B3: 6 | C3: Item | D3: 649 | E3: 10 | H3: =VLOOKUP(B3,Quests!A:C,2,0) -> Sheep Wool | I3: =IF(C3 = "Item", VLOOKUP(D3,Items!A:C,3,0), IF(OR(C3 = "Kill", C3 = "TalkToNPC"), VLOOKUP(D3,NPCs!A:C,3,0), "")) -> Wool
A4: 3 | B4: 7 | C4: Item | D4: 7 | E4: 10 | H4: =VLOOKUP(B4,Quests!A:C,2,0) -> Jack's Jacket | I4: =IF(C4 = "Item", VLOOKUP(D4,Items!A:C,3,0), IF(OR(C4 = "Kill", C4 = "TalkToNPC"), VLOOKUP(D4,NPCs!A:C,3,0), "")) -> Rabbit Fur
A5: 4 | B5: 7 | C5: Item | D5: 8 | E5: 10 | H5: =VLOOKUP(B5,Quests!A:C,2,0) -> Jack's Jacket | I5: =IF(C5 = "Item", VLOOKUP(D5,Items!A:C,3,0), IF(OR(C5 = "Kill", C5 = "TalkToNPC"), VLOOKUP(D5,NPCs!A:C,3,0), "")) -> Rabbit Pelt
A6: 5 | B6: 7 | C6: TalkToNPC | D6: 188 | H6: =VLOOKUP(B6,Quests!A:C,2,0) -> Jack's Jacket | I6: =IF(C6 = "Item", VLOOKUP(D6,Items!A:C,3,0), IF(OR(C6 = "Kill", C6 = "TalkToNPC"), VLOOKUP(D6,NPCs!A:C,3,0), "")) -> Jill
A7: 6 | B7: 8 | C7: Kill | D7: 4 | E7: 20 | H7: =VLOOKUP(B7,Quests!A:C,2,0) -> Angry Rabbits | I7: =IF(C7 = "Item", VLOOKUP(D7,Items!A:C,3,0), IF(OR(C7 = "Kill", C7 = "TalkToNPC"), VLOOKUP(D7,NPCs!A:C,3,0), "")) -> Rabid Rabbit
A8: 7 | B8: 9 | C8: Kill | D8: 6 | E8: 20 | H8: =VLOOKUP(B8,Quests!A:C,2,0) -> Biting Asps | I8: =IF(C8 = "Item", VLOOKUP(D8,Items!A:C,3,0), IF(OR(C8 = "Kill", C8 = "TalkToNPC"), VLOOKUP(D8,NPCs!A:C,3,0), "")) -> Asp
A9: 8 | B9: 10 | C9: Kill | D9: 7 | E9: 25 | H9: =VLOOKUP(B9,Quests!A:C,2,0) -> Screeching Bats | I9: =IF(C9 = "Item", VLOOKUP(D9,Items!A:C,3,0), IF(OR(C9 = "Kill", C9 = "TalkToNPC"), VLOOKUP(D9,NPCs!A:C,3,0), "")) -> Bat

Sheet Quest Rewards
A1: id | B1: quest id | C1: reward type | D1: long value | E1: long value 2 | F1: string value | H1: Quest (Don't touch) | I1: Item Name (Don't touch)
A2: 1 | B2: 1 | C2: ClassChange | D2: 3 | H2: =VLOOKUP(B2,Quests!A:C,2,0) -> Path of the Warrior | I2: =IF(C2 = "Item", VLOOKUP(D2,Items!A:C,3,0), "")
A3: 2 | B3: 1 | C3: Item | D3: 644 | E3: 1 | H3: =VLOOKUP(B3,Quests!A:C,2,0) -> Path of the Warrior | I3: =IF(C3 = "Item", VLOOKUP(D3,Items!A:C,3,0), "") -> Dusty Shoes
A4: 3 | B4: 1 | C4: Item | D4: 648 | E4: 1 | H4: =VLOOKUP(B4,Quests!A:C,2,0) -> Path of the Warrior | I4: =IF(C4 = "Item", VLOOKUP(D4,Items!A:C,3,0), "") -> Rusty Sword
A5: 4 | B5: 2 | C5: ClassChange | D5: 4 | H5: =VLOOKUP(B5,Quests!A:C,2,0) -> Path of the Magus | I5: =IF(C5 = "Item", VLOOKUP(D5,Items!A:C,3,0), "")
A6: 5 | B6: 2 | C6: Item | D6: 644 | E6: 1 | H6: =VLOOKUP(B6,Quests!A:C,2,0) -> Path of the Magus | I6: =IF(C6 = "Item", VLOOKUP(D6,Items!A:C,3,0), "") -> Dusty Shoes
A7: 6 | B7: 2 | C7: Item | D7: 646 | E7: 1 | H7: =VLOOKUP(B7,Quests!A:C,2,0) -> Path of the Magus | I7: =IF(C7 = "Item", VLOOKUP(D7,Items!A:C,3,0), "") -> Old Stave
A8: 7 | B8: 2 | C8: Item | D8: 25 | E8: 1 | H8: =VLOOKUP(B8,Quests!A:C,2,0) -> Path of the Magus | I8: =IF(C8 = "Item", VLOOKUP(D8,Items!A:C,3,0), "") -> Scroll: Elemental Strike 1
A9: 8 | B9: 3 | C9: ClassChange | D9: 2 | H9: =VLOOKUP(B9,Quests!A:C,2,0) -> Path of the Rogue | I9: =IF(C9 = "Item", VLOOKUP(D9,Items!A:C,3,0), "")
A10: 9 | B10: 3 | C10: Item | D10: 644 | E10: 1 | H10: =VLOOKUP(B10,Quests!A:C,2,0) -> Path of the Rogue | I10: =IF(C10 = "Item", VLOOKUP(D10,Items!A:C,3,0), "") -> Dusty Shoes
A11: 10 | B11: 3 | C11: Item | D11: 647 | E11: 1 | H11: =VLOOKUP(B11,Quests!A:C,2,0) -> Path of the Rogue | I11: =IF(C11 = "Item", VLOOKUP(D11,Items!A:C,3,0), "") -> Rusty Dagger
A12: 11 | B12: 4 | C12: ClassChange | D12: 5 | H12: =VLOOKUP(B12,Quests!A:C,2,0) -> Path of the Priest | I12: =IF(C12 = "Item", VLOOKUP(D12,Items!A:C,3,0), "")
A13: 12 | B13: 4 | C13: Item | D13: 644 | E13: 1 | H13: =VLOOKUP(B13,Quests!A:C,2,0) -> Path of the Priest | I13: =IF(C13 = "Item", VLOOKUP(D13,Items!A:C,3,0), "") -> Dusty Shoes
A14: 13 | B14: 4 | C14: Item | D14: 645 | E14: 1 | H14: =VLOOKUP(B14,Quests!A:C,2,0) -> Path of the Priest | I14: =IF(C14 = "Item", VLOOKUP(D14,Items!A:C,3,0), "") -> Rusty Hammer
A15: 14 | B15: 4 | C15: Item | D15: 10 | E15: 1 | H15: =VLOOKUP(B15,Quests!A:C,2,0) -> Path of the Priest | I15: =IF(C15 = "Item", VLOOKUP(D15,Items!A:C,3,0), "") -> Scroll: Healing 1
A16: 15 | B16: 5 | C16: Item | D16: 4 | E16: 5 | H16: =VLOOKUP(B16,Quests!A:C,2,0) -> Mouse Killer | I16: =IF(C16 = "Item", VLOOKUP(D16,Items!A:C,3,0), "") -> Small Health Potion
A17: 16 | B17: 5 | C17: Item | D17: 5 | E17: 5 | H17: =VLOOKUP(B17,Quests!A:C,2,0) -> Mouse Killer | I17: =IF(C17 = "Item", VLOOKUP(D17,Items!A:C,3,0), "") -> Small Mana Potion
A18: 17 | B18: 5 | C18: Gold | D18: 2000 | H18: =VLOOKUP(B18,Quests!A:C,2,0) -> Mouse Killer | I18: =IF(C18 = "Item", VLOOKUP(D18,Items!A:C,3,0), "")
A19: 18 | B19: 6 | C19: Gold | D19: 2500 | H19: =VLOOKUP(B19,Quests!A:C,2,0) -> Sheep Wool | I19: =IF(C19 = "Item", VLOOKUP(D19,Items!A:C,3,0), "")
A20: 19 | B20: 6 | C20: Experience | D20: 1000 | H20: =VLOOKUP(B20,Quests!A:C,2,0) -> Sheep Wool | I20: =IF(C20 = "Item", VLOOKUP(D20,Items!A:C,3,0), "")
A21: 20 | B21: 7 | C21: Gold | D21: 3000 | H21: =VLOOKUP(B21,Quests!A:C,2,0) -> Jack's Jacket | I21: =IF(C21 = "Item", VLOOKUP(D21,Items!A:C,3,0), "")
A22: 21 | B22: 7 | C22: Experience | D22: 2000 | H22: =VLOOKUP(B22,Quests!A:C,2,0) -> Jack's Jacket | I22: =IF(C22 = "Item", VLOOKUP(D22,Items!A:C,3,0), "")
A23: 22 | B23: 7 | C23: Item | D23: 650 | E23: 1 | H23: =VLOOKUP(B23,Quests!A:C,2,0) -> Jack's Jacket | I23: =IF(C23 = "Item", VLOOKUP(D23,Items!A:C,3,0), "") -> Rabbit Fur Pants
A24: 23 | B24: 8 | C24: Experience | D24: 2500 | H24: =VLOOKUP(B24,Quests!A:C,2,0) -> Angry Rabbits | I24: =IF(C24 = "Item", VLOOKUP(D24,Items!A:C,3,0), "")
A25: 24 | B25: 9 | C25: Experience | D25: 3000 | H25: =VLOOKUP(B25,Quests!A:C,2,0) -> Biting Asps | I25: =IF(C25 = "Item", VLOOKUP(D25,Items!A:C,3,0), "")
A26: 25 | B26: 10 | C26: Experience | D26: 5000 | H26: =VLOOKUP(B26,Quests!A:C,2,0) -> Screeching Bats | I26: =IF(C26 = "Item", VLOOKUP(D26,Items!A:C,3,0), "")

Sheet Titles
A1: id | B1: name | C1: min level (1) | D1: max level (50) | E1: min xp (0) | F1: max xp (0) | G1: item_usetype | H1: item_slot (Misc) | I1: chance | J1: script_path | K1: script_params
A2: 1 | B2: Powerful | I2: 0.5 | J2: Scripts/Item/ItemModifierScript.csx | K2: [{ "type": "statMultiplier", "value": 2.0 }]
A3: 2 | B3: Strong | I3: 0.5 | J3: Scripts/Item/ItemModifierScript.csx | K3: [{ "type": "statMultiplier", "value": 1.5 }]
A4: 3 | B4: Broken | I4: 0.5 | J4: Scripts/Item/ItemModifierScript.csx | K4: [{ "type": "statMultiplier", "value": 0.5 }]
A5: 4 | B5: Sharp | G5: Weapon | I5: 0.5 | J5: Scripts/Item/ItemModifierScript.csx | K5: [{ "type": "weaponDamage", "min": 5, "max": 10 }]

Sheet Surnames
A1: id | B1: name | C1: min level (1) | D1: max level (50) | E1: min xp (0) | F1: max xp (0) | G1: item_usetype | H1: item_slot (Misc) | I1: chance | J1: script_path | K1: script_params
A2: 1 | B2: of Vitality | I2: 0.5 | J2: Scripts/Item/ItemModifierScript.csx | K2: [{ "type": "hp", "min": 10, "max": 20 }]
A3: 2 | B3: of Intelligence | I3: 0.5 | J3: Scripts/Item/ItemModifierScript.csx | K3: [{ "type": "int", "min": 1, "max": 10 }]
A4: 3 | B4: of the Bear | G4: Weapon | I4: 0.5 | J4: Scripts/Item/ItemModifierScript.csx | K4: [{ "type": "str", "min": 1, "max": 10 }]
A5: 4 | B5: of the Turtle | G5: Armor | I5: 0.5 | J5: Scripts/Item/ItemModifierScript.csx | K5: [{ "type": "ac", "min": 1, "max": 10 }]
A6: 5 | B6: of Spell Damage | I6: 0.5 | J6: Scripts/Item/ItemModifierScript.csx | K6: [{ "type": "spellDamage", "min": 1, "max": 10 }]

Sheet Classes
A1: id | B1: name | C1: ac_multiplier | D1: vita_cost | E1: mana_cost
A2: 1 | B2: Commoner | C2: 1 | D2: 10000 | E2: 10000
A3: 2 | B3: Rogue | C3: 0.65 | D3: 150000 | E3: 150000
A4: 3 | B4: Warrior | C4: 1 | D4: 100000 | E4: 200000
A5: 4 | B5: Magus | C5: 0.5 | D5: 200000 | E5: 100000
A6: 5 | B6: Priest | C6: 0.7 | D6: 180000 | E6: 120000
A7: 6 | B7: Game Master | C7: 1 | D7: 100000 | E7: 100000

Sheet Class Info
A1: class_id | B1: level | C1: level_up_exp | D1: hp | E1: mp | F1: sp | G1: ac | H1: str | I1: sta | J1: dex | K1: int | L1: fr | M1: wr | N1: sr | O1: ar | P1: er | Q1: hp % reg | R1: hp static reg | S1: mp % reg | T1: mp static reg | U1: haste | V1: sd | W1: sc | X1: melee d | Y1: melee c | Z1: dmg reduce | AB1: Class Name
A2: 1 | B2: 1 | C2: 200 | D2: 30 | E2: 30 | AB2: =VLOOKUP(A2,Classes!A:C,2,0) -> Commoner
A3: 1 | B3: 2 | C3: 800 | D3: 38 | E3: 38 | AB3: =VLOOKUP(A3,Classes!A:C,2,0) -> Commoner
A4: 1 | B4: 3 | C4: 2000 | D4: 50 | E4: 50 | AB4: =VLOOKUP(A4,Classes!A:C,2,0) -> Commoner
A5: 1 | B5: 4 | C5: 4000 | D5: 66 | E5: 66 | AB5: =VLOOKUP(A5,Classes!A:C,2,0) -> Commoner
A6: 1 | B6: 5 | C6: 0 | D6: 86 | E6: 86 | AB6: =VLOOKUP(A6,Classes!A:C,2,0) -> Commoner
A7: 2 | B7: 1 | C7: 200 | D7: 30 | E7: 30 | AB7: =VLOOKUP(A7,Classes!A:C,2,0) -> Rogue
A8: 2 | B8: 2 | C8: 800 | D8: 38 | E8: 38 | AB8: =VLOOKUP(A8,Classes!A:C,2,0) -> Rogue
A9: 2 | B9: 3 | C9: 2000 | D9: 50 | E9: 50 | AB9: =VLOOKUP(A9,Classes!A:C,2,0) -> Rogue
A10: 2 | B10: 4 | C10: 4000 | D10: 66 | E10: 66 | AB10: =VLOOKUP(A10,Classes!A:C,2,0) -> Rogue
A11: 2 | B11: 5 | C11: 7000 | D11: 86 | E11: 86 | AB11: =VLOOKUP(A11,Classes!A:C,2,0) -> Rogue
A12: 2 | B12: 6 | C12: 11200 | D12: 110 | E12: 110 | AB12: =VLOOKUP(A12,Classes!A:C,2,0) -> Rogue
A13: 2 | B13: 7 | C13: 16800 | D13: 138 | E13: 138 | AB13: =VLOOKUP(A13,Classes!A:C,2,0) -> Rogue
... A56: 2 | B56: 50 | C56: 0 | D56: 5200 | E56: 5200 | AB56: =VLOOKUP(A56,Classes!A:C,2,0) -> Rogue
A57: 3 | B57: 1 | C57: 200 | D57: 30 | E57: 30 | G57: 10 | AB57: =VLOOKUP(A57,Classes!A:C,2,0) -> Warrior
A58: 3 | B58: 2 | C58: 800 | D58: 42 | E58: 36 | G58: 20 | AB58: =VLOOKUP(A58,Classes!A:C,2,0) -> Warrior
A59: 3 | B59: 3 | C59: 2000 | D59: 60 | E59: 45 | G59: 30 | AB59: =VLOOKUP(A59,Classes!A:C,2,0) -> Warrior
A60: 3 | B60: 4 | C60: 4000 | D60: 84 | E60: 57 | G60: 40 | AB60: =VLOOKUP(A60,Classes!A:C,2,0) -> Warrior
A61: 3 | B61: 5 | C61: 7000 | D61: 114 | E61: 72 | G61: 50 | AB61: =VLOOKUP(A61,Classes!A:C,2,0) -> Warrior
A62: 3 | B62: 6 | C62: 11200 | D62: 150 | E62: 90 | G62: 60 | AB62: =VLOOKUP(A62,Classes!A:C,2,0) -> Warrior
A63: 3 | B63: 7 | C63: 16800 | D63: 192 | E63: 111 | G63: 70 | AB63: =VLOOKUP(A63,Classes!A:C,2,0) -> Warrior
A64: 3 | B64: 8 | C64: 24000 | D64: 240 | E64: 135 | G64: 80 | AB64: =VLOOKUP(A64,Classes!A:C,2,0) -> Warrior
A65: 3 | B65: 9 | C65: 33000 | D65: 294 | E65: 162 | G65: 90 | AB65: =VLOOKUP(A65,Classes!A:C,2,0) -> Warrior
A66: 3 | B66: 10 | C66: 44000 | D66: 354 | E66: 192 | G66: 100 | AB66: =VLOOKUP(A66,Classes!A:C,2,0) -> Warrior
A67: 3 | B67: 11 | C67: 57200 | D67: 420 | E67: 225 | G67: 110 | AB67: =VLOOKUP(A67,Classes!A:C,2,0) -> Warrior
A68: 3 | B68: 12 | C68: 72800 | D68: 492 | E68: 261 | G68: 120 | AB68: =VLOOKUP(A68,Classes!A:C,2,0) -> Warrior
... A106: 3 | B106: 50 | C106: 0 | D106: 7700 | E106: 3900 | G106: 500 | AB106: =VLOOKUP(A106,Classes!A:C,2,0) -> Warrior
A107: 4 | B107: 1 | C107: 200 | D107: 30 | E107: 30 | AB107: =VLOOKUP(A107,Classes!A:C,2,0) -> Magus
A108: 4 | B108: 2 | C108: 800 | D108: 36 | E108: 42 | AB108: =VLOOKUP(A108,Classes!A:C,2,0) -> Magus
A109: 4 | B109: 3 | C109: 2000 | D109: 45 | E109: 60 | AB109: =VLOOKUP(A109,Classes!A:C,2,0) -> Magus
A110: 4 | B110: 4 | C110: 4000 | D110: 57 | E110: 84 | AB110: =VLOOKUP(A110,Classes!A:C,2,0) -> Magus
A111: 4 | B111: 5 | C111: 7000 | D111: 72 | E111: 114 | AB111: =VLOOKUP(A111,Classes!A:C,2,0) -> Magus
A112: 4 | B112: 6 | C112: 11200 | D112: 90 | E112: 150 | AB112: =VLOOKUP(A112,Classes!A:C,2,0) -> Magus
A113: 4 | B113: 7 | C113: 16800 | D113: 111 | E113: 192 | AB113: =VLOOKUP(A113,Classes!A:C,2,0) -> Magus
A114: 4 | B114: 8 | C114: 24000 | D114: 135 | E114: 240 | AB114: =VLOOKUP(A114,Classes!A:C,2,0) -> Magus
A115: 4 | B115: 9 | C115: 33000 | D115: 162 | E115: 294 | AB115: =VLOOKUP(A115,Classes!A:C,2,0) -> Magus
A116: 4 | B116: 10 | C116: 44000 | D116: 192 | E116: 354 | AB116: =VLOOKUP(A116,Classes!A:C,2,0) -> Magus
A117: 4 | B117: 11 | C117: 57200 | D117: 225 | E117: 420 | AB117: =VLOOKUP(A117,Classes!A:C,2,0) -> Magus
A118: 4 | B118: 12 | C118: 72800 | D118: 261 | E118: 492 | AB118: =VLOOKUP(A118,Classes!A:C,2,0) -> Magus
... A256: 6 | B256: 50 | C256: 0 | D256: 4300 | E256: 6400 | AB256: =VLOOKUP(A256,Classes!A:C,2,0) -> Game Master

Sheet Class Levelup Spells
A1: class id | B1: level | C1: spell id | E1: Class Name | F1: Spell Name
A2: 2 | B2: 4 | C2: 3 | E2: =VLOOKUP(A2,Classes!A:C,2,0) -> Rogue | F2: =VLOOKUP(C2,Spells!A:C,2,0) -> Backstab 1
A3: 2 | B3: 11 | C3: 25 | E3: =VLOOKUP(A3,Classes!A:C,2,0) -> Rogue | F3: =VLOOKUP(C3,Spells!A:C,2,0) -> Poison Weapon 1
A4: 2 | B4: 14 | C4: 26 | E4: =VLOOKUP(A4,Classes!A:C,2,0) -> Rogue | F4: =VLOOKUP(C4,Spells!A:C,2,0) -> Backstab 2
A5: 2 | B5: 19 | C5: 27 | E5: =VLOOKUP(A5,Classes!A:C,2,0) -> Rogue | F5: =VLOOKUP(C5,Spells!A:C,2,0) -> Nimble 1
A6: 2 | B6: 24 | C6: 28 | E6: =VLOOKUP(A6,Classes!A:C,2,0) -> Rogue | F6: =VLOOKUP(C6,Spells!A:C,2,0) -> Backstab 3
A7: 2 | B7: 28 | C7: 81 | E7: =VLOOKUP(A7,Classes!A:C,2,0) -> Rogue | F7: =VLOOKUP(C7,Spells!A:C,2,0) -> Invisibility
A8: 2 | B8: 31 | C8: 82 | E8: =VLOOKUP(A8,Classes!A:C,2,0) -> Rogue | F8: =VLOOKUP(C8,Spells!A:C,2,0) -> Poison Weapon 2
A9: 2 | B9: 34 | C9: 83 | E9: =VLOOKUP(A9,Classes!A:C,2,0) -> Rogue | F9: =VLOOKUP(C9,Spells!A:C,2,0) -> Backstab 4
A10: 2 | B10: 39 | C10: 84 | E10: =VLOOKUP(A10,Classes!A:C,2,0) -> Rogue | F10: =VLOOKUP(C10,Spells!A:C,2,0) -> Nimble 2
A11: 2 | B11: 44 | C11: 85 | E11: =VLOOKUP(A11,Classes!A:C,2,0) -> Rogue | F11: =VLOOKUP(C11,Spells!A:C,2,0) -> Backstab 5
A12: 3 | B12: 1 | C12: 4 | E12: =VLOOKUP(A12,Classes!A:C,2,0) -> Warrior | F12: =VLOOKUP(C12,Spells!A:C,2,0) -> Taunt 1
A13: 3 | B13: 5 | C13: 20 | E13: =VLOOKUP(A13,Classes!A:C,2,0) -> Warrior | F13: =VLOOKUP(C13,Spells!A:C,2,0) -> Rampant Rage
... A26: 3 | B26: 49 | C26: 87 | E26: =VLOOKUP(A26,Classes!A:C,2,0) -> Warrior | F26: =VLOOKUP(C26,Spells!A:C,2,0) -> Ground Slam 4
