Workbook

Sheet README
A1: Goose balance model - how to use
A3: Purpose | B3: Expected damage per level for each class against a typical same-level trash mob: hits to kill, melee vs spell damage, DPS, time to kill and HP lost.
A4: Edit | B4: Inputs sheet: yellow cells are the scenario levers (gear profile, mob level offset, specific mob, backstab-from-behind share, cast interval).
A5: Edit | B5: Gear sheet: profile 3 is a free what-if copy of profile 2 - change stats there to test item changes without touching the game data.
A6: Edit | B6: Abilities sheet: tier tables for Backstab, Elemental Strike, Berserker, Rampant Rage/Savage Fury, Nimble, Poison, Strength.
A7: Edit | B7: Accessory Proposals sheet: blue proposed stats/effects per accessory (effect is a dropdown). % of target updates live. Item Budget sheet holds the point weights and source multipliers (yellow).
A8: Item budget | B8: Each accessory slot gets a budget line fitted to the new accessory set (items 661-696). Target = budget at the item level x source multiplier (+ class-restricted bonus). Points: 25 HP = 1 STA = 1 point, 1 STR = 2, effects per 1% (DR 8, melee dmg / haste 6, spell dmg 5, crit 4). Value = the better of a melee or a caster reading.
A9: Endgame reading | B9: At 10M+ XP every class uses % current HP/MP spells (Spirit Strike, Sunder of Spirits, Critical Strike, Fearsome Lash, Arcane Blast, Arcane Assault), so melee stats are ignored. L40+ accessories are scored for one reference player (Item Budget, yellow): spell damage + spell crit + HP/MP as a % of the pool that XP buys + DR + AC. In each slot, the best item of each XP tier must beat the best item of any lower XP tier by the margin (XP tier check column).
A10: Colours | B10: Blue = hardcoded input/data, black = formula, green = formula pulling from another sheet, yellow fill = main levers.
A11: Player melee | B11: hit = (STR + weapon dmg + level + avg(rand 1..level) + (level - mob level)) * crit * (1 + melee dmg%) * DamageModifier * (1 - mobAC*mult/MaxAC) - mobAC*mult/25 (Player.Attack)
A12: Swing time | B12: weapon delay/10 * (1 - min(0.95, haste)) * 0.85 s (PlayerAttackEvent)
A13: Spells | B13: Formula damage * (1 + spell dmg%) * crit(spell crit%) * DamageModifier. Spells ignore AC (SpellEffect.CalculateFormulaResults).
A14: Backstab | B14: -mult * (STR + weapon dmg + level), x1.5 when caster faces the same way as the target (Scripts/Spell/Backstab.csx).
... A24: Pass 2 | B24: 2026-09-29: second balancing pass on per-class weights (see Pass 2 Changes and Item Budget Class weights). Gear and Accessory Proposals now show live data as Current and pass 2 as Proposed. Pass 1, the Gold/Devastators rebalance and the NPC changes are already in the game data.

Sheet Summary
A1: Class balance summary by level
A2: All values are formulas over the class sheets. Change Inputs (gear profile, mob offset, specific mob) to re-run. | B2: Opponent | C2: Sustained DPS | G2: DPS vs Warrior | J2: Time to kill | N2: % HP lost per kill | R2: Detail | AA2: Exp per minute (kill time only)
A3: Level | B3: Mob HP | C3: Warrior DPS | D3: Rogue DPS | E3: Magus DPS | F3: Priest DPS | G3: Rogue / Warrior | H3: Magus / Warrior | I3: Priest / Warrior | J3: Warrior TTK s | K3: Rogue TTK s | L3: Magus TTK s | M3: Priest TTK s | N3: Warrior % HP / kill | O3: Rogue % HP / kill | P3: Magus % HP / kill | Q3: Priest % HP / kill | R3: Warrior swings to kill | S3: Rogue swings to kill | T3: Magus casts to kill | U3: Rogue backstab share | V3: Warrior chomp share | W3: Magus best ES tier (MP-limited) | X3: Warrior Fury targets | Y3: Magus targets per cast | Z3: Magus two-tier rotation DPS | AA3: Warrior exp / min | AB3: Rogue exp / min | AC3: Magus exp / min | AD3: Priest exp / min
A4: 1 | B4: ='Mob by Level'!C4 | C4: =Warrior!AK4 | D4: =Rogue!AI4 | E4: =Magus!BN4 | F4: =Priest!W4 | G4: =IFERROR(D4/C4,0) | H4: =IFERROR(E4/C4,0) | I4: =IFERROR(F4/C4,0) | J4: =Warrior!AO4 | K4: =Rogue!AM4 | L4: =Magus!BR4 | M4: =Priest!Y4 | N4: =Warrior!AR4 | O4: =Rogue!AP4 | P4: =Magus!BU4 | Q4: =Priest!AB4 | R4: =Warrior!AN4 | S4: =Rogue!AL4 | T4: =Magus!BK4 | U4: =Rogue!AK4 | V4: =Warrior!AM4 | W4: =Magus!BJ4 | X4: =Warrior!AG4 | Y4: =Magus!BF4 | Z4: =Magus!BP4 | AA4: =IFERROR('Mob by Level'!G4/Warrior!AO4*60,0) | AB4: =IFERROR('Mob by Level'!G4/Rogue!AM4*60,0) | AC4: =IFERROR('Mob by Level'!G4/Magus!BR4*60,0) | AD4: =IFERROR('Mob by Level'!G4/Priest!Y4*60,0)
A5: 2 | B5: ='Mob by Level'!C5 | C5: =Warrior!AK5 | D5: =Rogue!AI5 | E5: =Magus!BN5 | F5: =Priest!W5 | G5: =IFERROR(D5/C5,0) | H5: =IFERROR(E5/C5,0) | I5: =IFERROR(F5/C5,0) | J5: =Warrior!AO5 | K5: =Rogue!AM5 | L5: =Magus!BR5 | M5: =Priest!Y5 | N5: =Warrior!AR5 | O5: =Rogue!AP5 | P5: =Magus!BU5 | Q5: =Priest!AB5 | R5: =Warrior!AN5 | S5: =Rogue!AL5 | T5: =Magus!BK5 | U5: =Rogue!AK5 | V5: =Warrior!AM5 | W5: =Magus!BJ5 | X5: =Warrior!AG5 | Y5: =Magus!BF5 | Z5: =Magus!BP5 | AA5: =IFERROR('Mob by Level'!G5/Warrior!AO5*60,0) | AB5: =IFERROR('Mob by Level'!G5/Rogue!AM5*60,0) | AC5: =IFERROR('Mob by Level'!G5/Magus!BR5*60,0) | AD5: =IFERROR('Mob by Level'!G5/Priest!Y5*60,0)
A6: 3 | B6: ='Mob by Level'!C6 | C6: =Warrior!AK6 | D6: =Rogue!AI6 | E6: =Magus!BN6 | F6: =Priest!W6 | G6: =IFERROR(D6/C6,0) | H6: =IFERROR(E6/C6,0) | I6: =IFERROR(F6/C6,0) | J6: =Warrior!AO6 | K6: =Rogue!AM6 | L6: =Magus!BR6 | M6: =Priest!Y6 | N6: =Warrior!AR6 | O6: =Rogue!AP6 | P6: =Magus!BU6 | Q6: =Priest!AB6 | R6: =Warrior!AN6 | S6: =Rogue!AL6 | T6: =Magus!BK6 | U6: =Rogue!AK6 | V6: =Warrior!AM6 | W6: =Magus!BJ6 | X6: =Warrior!AG6 | Y6: =Magus!BF6 | Z6: =Magus!BP6 | AA6: =IFERROR('Mob by Level'!G6/Warrior!AO6*60,0) | AB6: =IFERROR('Mob by Level'!G6/Rogue!AM6*60,0) | AC6: =IFERROR('Mob by Level'!G6/Magus!BR6*60,0) | AD6: =IFERROR('Mob by Level'!G6/Priest!Y6*60,0)
A7: 4 | B7: ='Mob by Level'!C7 | C7: =Warrior!AK7 | D7: =Rogue!AI7 | E7: =Magus!BN7 | F7: =Priest!W7 | G7: =IFERROR(D7/C7,0) | H7: =IFERROR(E7/C7,0) | I7: =IFERROR(F7/C7,0) | J7: =Warrior!AO7 | K7: =Rogue!AM7 | L7: =Magus!BR7 | M7: =Priest!Y7 | N7: =Warrior!AR7 | O7: =Rogue!AP7 | P7: =Magus!BU7 | Q7: =Priest!AB7 | R7: =Warrior!AN7 | S7: =Rogue!AL7 | T7: =Magus!BK7 | U7: =Rogue!AK7 | V7: =Warrior!AM7 | W7: =Magus!BJ7 | X7: =Warrior!AG7 | Y7: =Magus!BF7 | Z7: =Magus!BP7 | AA7: =IFERROR('Mob by Level'!G7/Warrior!AO7*60,0) | AB7: =IFERROR('Mob by Level'!G7/Rogue!AM7*60,0) | AC7: =IFERROR('Mob by Level'!G7/Magus!BR7*60,0) | AD7: =IFERROR('Mob by Level'!G7/Priest!Y7*60,0)
A8: 5 | B8: ='Mob by Level'!C8 | C8: =Warrior!AK8 | D8: =Rogue!AI8 | E8: =Magus!BN8 | F8: =Priest!W8 | G8: =IFERROR(D8/C8,0) | H8: =IFERROR(E8/C8,0) | I8: =IFERROR(F8/C8,0) | J8: =Warrior!AO8 | K8: =Rogue!AM8 | L8: =Magus!BR8 | M8: =Priest!Y8 | N8: =Warrior!AR8 | O8: =Rogue!AP8 | P8: =Magus!BU8 | Q8: =Priest!AB8 | R8: =Warrior!AN8 | S8: =Rogue!AL8 | T8: =Magus!BK8 | U8: =Rogue!AK8 | V8: =Warrior!AM8 | W8: =Magus!BJ8 | X8: =Warrior!AG8 | Y8: =Magus!BF8 | Z8: =Magus!BP8 | AA8: =IFERROR('Mob by Level'!G8/Warrior!AO8*60,0) | AB8: =IFERROR('Mob by Level'!G8/Rogue!AM8*60,0) | AC8: =IFERROR('Mob by Level'!G8/Magus!BR8*60,0) | AD8: =IFERROR('Mob by Level'!G8/Priest!Y8*60,0)
A9: 6 | B9: ='Mob by Level'!C9 | C9: =Warrior!AK9 | D9: =Rogue!AI9 | E9: =Magus!BN9 | F9: =Priest!W9 | G9: =IFERROR(D9/C9,0) | H9: =IFERROR(E9/C9,0) | I9: =IFERROR(F9/C9,0) | J9: =Warrior!AO9 | K9: =Rogue!AM9 | L9: =Magus!BR9 | M9: =Priest!Y9 | N9: =Warrior!AR9 | O9: =Rogue!AP9 | P9: =Magus!BU9 | Q9: =Priest!AB9 | R9: =Warrior!AN9 | S9: =Rogue!AL9 | T9: =Magus!BK9 | U9: =Rogue!AK9 | V9: =Warrior!AM9 | W9: =Magus!BJ9 | X9: =Warrior!AG9 | Y9: =Magus!BF9 | Z9: =Magus!BP9 | AA9: =IFERROR('Mob by Level'!G9/Warrior!AO9*60,0) | AB9: =IFERROR('Mob by Level'!G9/Rogue!AM9*60,0) | AC9: =IFERROR('Mob by Level'!G9/Magus!BR9*60,0) | AD9: =IFERROR('Mob by Level'!G9/Priest!Y9*60,0)
A10: 7 | B10: ='Mob by Level'!C10 | C10: =Warrior!AK10 | D10: =Rogue!AI10 | E10: =Magus!BN10 | F10: =Priest!W10 | G10: =IFERROR(D10/C10,0) | H10: =IFERROR(E10/C10,0) | I10: =IFERROR(F10/C10,0) | J10: =Warrior!AO10 | K10: =Rogue!AM10 | L10: =Magus!BR10 | M10: =Priest!Y10 | N10: =Warrior!AR10 | O10: =Rogue!AP10 | P10: =Magus!BU10 | Q10: =Priest!AB10 | R10: =Warrior!AN10 | S10: =Rogue!AL10 | T10: =Magus!BK10 | U10: =Rogue!AK10 | V10: =Warrior!AM10 | W10: =Magus!BJ10 | X10: =Warrior!AG10 | Y10: =Magus!BF10 | Z10: =Magus!BP10 | AA10: =IFERROR('Mob by Level'!G10/Warrior!AO10*60,0) | AB10: =IFERROR('Mob by Level'!G10/Rogue!AM10*60,0) | AC10: =IFERROR('Mob by Level'!G10/Magus!BR10*60,0) | AD10: =IFERROR('Mob by Level'!G10/Priest!Y10*60,0)
A11: 8 | B11: ='Mob by Level'!C11 | C11: =Warrior!AK11 | D11: =Rogue!AI11 | E11: =Magus!BN11 | F11: =Priest!W11 | G11: =IFERROR(D11/C11,0) | H11: =IFERROR(E11/C11,0) | I11: =IFERROR(F11/C11,0) | J11: =Warrior!AO11 | K11: =Rogue!AM11 | L11: =Magus!BR11 | M11: =Priest!Y11 | N11: =Warrior!AR11 | O11: =Rogue!AP11 | P11: =Magus!BU11 | Q11: =Priest!AB11 | R11: =Warrior!AN11 | S11: =Rogue!AL11 | T11: =Magus!BK11 | U11: =Rogue!AK11 | V11: =Warrior!AM11 | W11: =Magus!BJ11 | X11: =Warrior!AG11 | Y11: =Magus!BF11 | Z11: =Magus!BP11 | AA11: =IFERROR('Mob by Level'!G11/Warrior!AO11*60,0) | AB11: =IFERROR('Mob by Level'!G11/Rogue!AM11*60,0) | AC11: =IFERROR('Mob by Level'!G11/Magus!BR11*60,0) | AD11: =IFERROR('Mob by Level'!G11/Priest!Y11*60,0)
A12: 9 | B12: ='Mob by Level'!C12 | C12: =Warrior!AK12 | D12: =Rogue!AI12 | E12: =Magus!BN12 | F12: =Priest!W12 | G12: =IFERROR(D12/C12,0) | H12: =IFERROR(E12/C12,0) | I12: =IFERROR(F12/C12,0) | J12: =Warrior!AO12 | K12: =Rogue!AM12 | L12: =Magus!BR12 | M12: =Priest!Y12 | N12: =Warrior!AR12 | O12: =Rogue!AP12 | P12: =Magus!BU12 | Q12: =Priest!AB12 | R12: =Warrior!AN12 | S12: =Rogue!AL12 | T12: =Magus!BK12 | U12: =Rogue!AK12 | V12: =Warrior!AM12 | W12: =Magus!BJ12 | X12: =Warrior!AG12 | Y12: =Magus!BF12 | Z12: =Magus!BP12 | AA12: =IFERROR('Mob by Level'!G12/Warrior!AO12*60,0) | AB12: =IFERROR('Mob by Level'!G12/Rogue!AM12*60,0) | AC12: =IFERROR('Mob by Level'!G12/Magus!BR12*60,0) | AD12: =IFERROR('Mob by Level'!G12/Priest!Y12*60,0)
A13: 10 | B13: ='Mob by Level'!C13 | C13: =Warrior!AK13 | D13: =Rogue!AI13 | E13: =Magus!BN13 | F13: =Priest!W13 | G13: =IFERROR(D13/C13,0) | H13: =IFERROR(E13/C13,0) | I13: =IFERROR(F13/C13,0) | J13: =Warrior!AO13 | K13: =Rogue!AM13 | L13: =Magus!BR13 | M13: =Priest!Y13 | N13: =Warrior!AR13 | O13: =Rogue!AP13 | P13: =Magus!BU13 | Q13: =Priest!AB13 | R13: =Warrior!AN13 | S13: =Rogue!AL13 | T13: =Magus!BK13 | U13: =Rogue!AK13 | V13: =Warrior!AM13 | W13: =Magus!BJ13 | X13: =Warrior!AG13 | Y13: =Magus!BF13 | Z13: =Magus!BP13 | AA13: =IFERROR('Mob by Level'!G13/Warrior!AO13*60,0) | AB13: =IFERROR('Mob by Level'!G13/Rogue!AM13*60,0) | AC13: =IFERROR('Mob by Level'!G13/Magus!BR13*60,0) | AD13: =IFERROR('Mob by Level'!G13/Priest!Y13*60,0)
A14: 11 | B14: ='Mob by Level'!C14 | C14: =Warrior!AK14 | D14: =Rogue!AI14 | E14: =Magus!BN14 | F14: =Priest!W14 | G14: =IFERROR(D14/C14,0) | H14: =IFERROR(E14/C14,0) | I14: =IFERROR(F14/C14,0) | J14: =Warrior!AO14 | K14: =Rogue!AM14 | L14: =Magus!BR14 | M14: =Priest!Y14 | N14: =Warrior!AR14 | O14: =Rogue!AP14 | P14: =Magus!BU14 | Q14: =Priest!AB14 | R14: =Warrior!AN14 | S14: =Rogue!AL14 | T14: =Magus!BK14 | U14: =Rogue!AK14 | V14: =Warrior!AM14 | W14: =Magus!BJ14 | X14: =Warrior!AG14 | Y14: =Magus!BF14 | Z14: =Magus!BP14 | AA14: =IFERROR('Mob by Level'!G14/Warrior!AO14*60,0) | AB14: =IFERROR('Mob by Level'!G14/Rogue!AM14*60,0) | AC14: =IFERROR('Mob by Level'!G14/Magus!BR14*60,0) | AD14: =IFERROR('Mob by Level'!G14/Priest!Y14*60,0)
A15: 12 | B15: ='Mob by Level'!C15 | C15: =Warrior!AK15 | D15: =Rogue!AI15 | E15: =Magus!BN15 | F15: =Priest!W15 | G15: =IFERROR(D15/C15,0) | H15: =IFERROR(E15/C15,0) | I15: =IFERROR(F15/C15,0) | J15: =Warrior!AO15 | K15: =Rogue!AM15 | L15: =Magus!BR15 | M15: =Priest!Y15 | N15: =Warrior!AR15 | O15: =Rogue!AP15 | P15: =Magus!BU15 | Q15: =Priest!AB15 | R15: =Warrior!AN15 | S15: =Rogue!AL15 | T15: =Magus!BK15 | U15: =Rogue!AK15 | V15: =Warrior!AM15 | W15: =Magus!BJ15 | X15: =Warrior!AG15 | Y15: =Magus!BF15 | Z15: =Magus!BP15 | AA15: =IFERROR('Mob by Level'!G15/Warrior!AO15*60,0) | AB15: =IFERROR('Mob by Level'!G15/Rogue!AM15*60,0) | AC15: =IFERROR('Mob by Level'!G15/Magus!BR15*60,0) | AD15: =IFERROR('Mob by Level'!G15/Priest!Y15*60,0)
... A52: 49 | B52: ='Mob by Level'!C52 | C52: =Warrior!AK52 | D52: =Rogue!AI52 | E52: =Magus!BN52 | F52: =Priest!W52 | G52: =IFERROR(D52/C52,0) | H52: =IFERROR(E52/C52,0) | I52: =IFERROR(F52/C52,0) | J52: =Warrior!AO52 | K52: =Rogue!AM52 | L52: =Magus!BR52 | M52: =Priest!Y52 | N52: =Warrior!AR52 | O52: =Rogue!AP52 | P52: =Magus!BU52 | Q52: =Priest!AB52 | R52: =Warrior!AN52 | S52: =Rogue!AL52 | T52: =Magus!BK52 | U52: =Rogue!AK52 | V52: =Warrior!AM52 | W52: =Magus!BJ52 | X52: =Warrior!AG52 | Y52: =Magus!BF52 | Z52: =Magus!BP52 | AA52: =IFERROR('Mob by Level'!G52/Warrior!AO52*60,0) | AB52: =IFERROR('Mob by Level'!G52/Rogue!AM52*60,0) | AC52: =IFERROR('Mob by Level'!G52/Magus!BR52*60,0) | AD52: =IFERROR('Mob by Level'!G52/Priest!Y52*60,0)

Sheet Inputs
A1: Balance model inputs
A2: Blue cells are inputs; yellow cells are the main scenario levers. Every other sheet recalculates from these.
A4: Setting | C4: Value | D4: Source / meaning
A5: Gear profile (1 = vendor only, 2 = vendor + new accessories, 3 = what-if) | C5: 2 | D5: Selects which block of the Gear sheet every class uses.
A6: Mob level offset (mob level = player level + offset) | C6: 0 | D6: Negative = fighting lower-level mobs. Affects the (level - target level) term in both hit formulas.
A7: Specific mob name (blank = typical trash mob for the level) | D7: Exact name from the Mobs sheet. When set, every level fights this one mob.
A8: Typical-mob level window (+/- levels) | C8: 3 | D8: Typical mob = average of trash mobs within this many levels.
A9: Trash mob: max respawn time (s) | C9: 120 | D9: Mobs with a longer respawn are treated as bosses/named and excluded from the typical mob.
A10: Trash mob: min spawn count | C10: 5 | D10: Mobs placed fewer times than this are excluded from the typical mob.
A11: Share of backstabs landed from behind (0-1) | C11: 0.5 | D11: Backstab.csx: x1.5 damage when caster.Facing == target.Facing.
A12: Minimum seconds between spell casts (human/client limit) | C12: 0.5 | D12: Server only enforces per-slot aether; no global cooldown exists (Player.cs CastSpell).
A13: Area targets (Magus ES, Warrior Savage Fury): 1 = single target, 2 = expected, 3 = max | C13: 2 | D13: Area ES tiers (5, 6, 7, 8) and Savage Fury can hit several mobs. Expected/max come from the Elemental Strike and Chomp tables on the Abilities sheet.
A14: Mobs in a pack (including the target) | C14: 5 | D14: Caps max targets and drives expected targets.
A15: Share of area casts that land on a pack (0-1) | C15: 0.5 | D15: The rest of the time only the main target is in the area.
A16: Include class cooldown buffs in sustained DPS (1/0) | C16: 1 | D16: Rampant Rage, Savage Fury, Berserker, Nimble, Poison Weapon are averaged by uptime = duration / cooldown.
A17: Priest Strength buff on every class (1/0) | C17: 0 | D17: Adds the Strength tier for the player level (Abilities sheet). Priests always get it on themselves.
A18: Magus melees alongside casting (1/0) | C18: 0 | D18: Adds staff melee DPS to Magus sustained DPS.
A19: MaxAC setting | C19: 3500 | D19: GooseSettings.json MaxAC. absorb = 1 - AC*ACMultiplier/MaxAC.
... A25: Tick spell period (s) | C25: 2 | D25: GooseSettings.json SpellEffectPeriod (poison ticks).

Sheet Class Table
A1: Class base stats by level
A2: Source: game data sheet "Class Info" (Aspereta Goose Data, Illutia). Blue = copied data.
A3: Level | B3: Rogue HP | C3: Rogue MP | D3: Rogue AC | E3: Warrior HP | F3: Warrior MP | G3: Warrior AC | H3: Magus HP | I3: Magus MP | J3: Magus AC | K3: Priest HP | L3: Priest MP | M3: Priest AC | N3: Class | O3: AC multiplier
A4: 1 | B4: 30 | C4: 30 | D4: 0 | E4: 30 | F4: 30 | G4: 10 | H4: 30 | I4: 30 | J4: 0 | K4: 30 | L4: 30 | M4: 0 | N4: 1 | O4: 1
A5: 2 | B5: 38 | C5: 38 | D5: 0 | E5: 42 | F5: 36 | G5: 20 | H5: 36 | I5: 42 | J5: 0 | K5: 37 | L5: 40 | M5: 0 | N5: 2 | O5: 0.65
A6: 3 | B6: 50 | C6: 50 | D6: 0 | E6: 60 | F6: 45 | G6: 30 | H6: 45 | I6: 60 | J6: 0 | K6: 47 | L6: 55 | M6: 0 | N6: 3 | O6: 1
A7: 4 | B7: 66 | C7: 66 | D7: 0 | E7: 84 | F7: 57 | G7: 40 | H7: 57 | I7: 84 | J7: 0 | K7: 61 | L7: 75 | M7: 0 | N7: 4 | O7: 0.5
A8: 5 | B8: 86 | C8: 86 | D8: 0 | E8: 114 | F8: 72 | G8: 50 | H8: 72 | I8: 114 | J8: 0 | K8: 78 | L8: 100 | M8: 0 | N8: 5 | O8: 0.7
A9: 6 | B9: 110 | C9: 110 | D9: 0 | E9: 150 | F9: 90 | G9: 60 | H9: 90 | I9: 150 | J9: 0 | K9: 98 | L9: 130 | M9: 0 | N9: 6 | O9: 1
A10: 7 | B10: 138 | C10: 138 | D10: 0 | E10: 192 | F10: 111 | G10: 70 | H10: 111 | I10: 192 | J10: 0 | K10: 122 | L10: 165 | M10: 0
A11: 8 | B11: 170 | C11: 170 | D11: 0 | E11: 240 | F11: 135 | G11: 80 | H11: 135 | I11: 240 | J11: 0 | K11: 149 | L11: 205 | M11: 0
A12: 9 | B12: 206 | C12: 206 | D12: 0 | E12: 294 | F12: 162 | G12: 90 | H12: 162 | I12: 294 | J12: 0 | K12: 179 | L12: 250 | M12: 0 | N12: Class ids: 2 Rogue, 3 Warrior, 4 Magus, 5 Priest. Source: "Classes" sheet.
A13: 10 | B13: 246 | C13: 246 | D13: 0 | E13: 354 | F13: 192 | G13: 100 | H13: 192 | I13: 354 | J13: 0 | K13: 213 | L13: 300 | M13: 0
A14: 11 | B14: 290 | C14: 290 | D14: 0 | E14: 420 | F14: 225 | G14: 110 | H14: 225 | I14: 420 | J14: 0 | K14: 250 | L14: 355 | M14: 0
A15: 12 | B15: 338 | C15: 338 | D15: 0 | E15: 492 | F15: 261 | G15: 120 | H15: 261 | I15: 492 | J15: 0 | K15: 290 | L15: 415 | M15: 0
A16: 13 | B16: 390 | C16: 390 | D16: 0 | E16: 570 | F16: 300 | G16: 130 | H16: 300 | I16: 570 | J16: 0 | K16: 334 | L16: 480 | M16: 0
A17: 14 | B17: 446 | C17: 446 | D17: 0 | E17: 654 | F17: 342 | G17: 140 | H17: 342 | I17: 654 | J17: 0 | K17: 381 | L17: 550 | M17: 0
A18: 15 | B18: 506 | C18: 506 | D18: 0 | E18: 744 | F18: 387 | G18: 150 | H18: 387 | I18: 744 | J18: 0 | K18: 431 | L18: 625 | M18: 0
A19: 16 | B19: 570 | C19: 570 | D19: 0 | E19: 840 | F19: 435 | G19: 160 | H19: 435 | I19: 840 | J19: 0 | K19: 485 | L19: 705 | M19: 0
A20: 17 | B20: 638 | C20: 638 | D20: 0 | E20: 942 | F20: 486 | G20: 170 | H20: 486 | I20: 942 | J20: 0 | K20: 542 | L20: 790 | M20: 0
A21: 18 | B21: 710 | C21: 710 | D21: 0 | E21: 1050 | F21: 540 | G21: 180 | H21: 540 | I21: 1050 | J21: 0 | K21: 602 | L21: 880 | M21: 0
A22: 19 | B22: 786 | C22: 786 | D22: 0 | E22: 1164 | F22: 597 | G22: 190 | H22: 597 | I22: 1164 | J22: 0 | K22: 666 | L22: 975 | M22: 0
A23: 20 | B23: 866 | C23: 866 | D23: 0 | E23: 1284 | F23: 657 | G23: 200 | H23: 657 | I23: 1284 | J23: 0 | K23: 733 | L23: 1075 | M23: 0
A24: 21 | B24: 950 | C24: 950 | D24: 0 | E24: 1410 | F24: 720 | G24: 210 | H24: 720 | I24: 1410 | J24: 0 | K24: 803 | L24: 1180 | M24: 0
... A53: 50 | B53: 5200 | C53: 5200 | D53: 0 | E53: 7700 | F53: 3900 | G53: 500 | H53: 3852 | I53: 7674 | J53: 0 | K53: 4300 | L53: 6400 | M53: 0

Sheet Gear
A1: Gear profiles by class and level
A2: Totals of equipped item stats (STA x25 already folded into HP, INT x25 into MP; % stats come from the item equip effect). Profile 3 starts as a copy of 2 - edit it for what-ifs.
A3: Level | B3: Class | C3: Profile | D3: Weapon dmg | E3: Weapon delay | F3: STR | G3: HP | H3: MP | I3: AC | J3: Spell dmg % | K3: Spell crit % | L3: Melee dmg % | M3: Melee crit % | N3: Haste % | O3: Dmg reduce % | P3: Items
A4: 1 | B4: Rogue | C4: 1 | D4: 3 | E4: 10 | F4: 0 | G4: 0 | H4: 0 | I4: 25 | J4: 0 | K4: 0 | L4: 0 | M4: 0 | N4: 0 | O4: 0 | P4: Cloth Tunic, Cloth Cap, Cloth Leggings, Cloth Shoes, Stick
A5: 2 | B5: Rogue | C5: 1 | D5: 3 | E5: 10 | F5: 0 | G5: 0 | H5: 0 | I5: 25 | J5: 0 | K5: 0 | L5: 0 | M5: 0 | N5: 0 | O5: 0 | P5: Cloth Tunic, Cloth Cap, Cloth Leggings, Cloth Shoes, Stick
A6: 3 | B6: Rogue | C6: 1 | D6: 3 | E6: 10 | F6: 0 | G6: 0 | H6: 0 | I6: 25 | J6: 0 | K6: 0 | L6: 0 | M6: 0 | N6: 0 | O6: 0 | P6: Cloth Tunic, Cloth Cap, Cloth Leggings, Cloth Shoes, Stick
A7: 4 | B7: Rogue | C7: 1 | D7: 3 | E7: 10 | F7: 0 | G7: 0 | H7: 0 | I7: 25 | J7: 0 | K7: 0 | L7: 0 | M7: 0 | N7: 0 | O7: 0 | P7: Cloth Tunic, Cloth Cap, Cloth Leggings, Cloth Shoes, Stick
A8: 5 | B8: Rogue | C8: 1 | D8: 12 | E8: 10 | F8: 0 | G8: 0 | H8: 0 | I8: 35 | J8: 0 | K8: 0 | L8: 0 | M8: 0 | N8: 0 | O8: 0 | P8: Cloth Tunic, Cloth Cap, Cloth Leggings, Cloth Shoes, Small Dagger, Wooden Buckler
A9: 6 | B9: Rogue | C9: 1 | D9: 12 | E9: 10 | F9: 0 | G9: 0 | H9: 0 | I9: 35 | J9: 0 | K9: 0 | L9: 0 | M9: 0 | N9: 0 | O9: 0 | P9: Cloth Tunic, Cloth Cap, Cloth Leggings, Cloth Shoes, Small Dagger, Wooden Buckler
A10: 7 | B10: Rogue | C10: 1 | D10: 12 | E10: 10 | F10: 0 | G10: 0 | H10: 0 | I10: 35 | J10: 0 | K10: 0 | L10: 0 | M10: 0 | N10: 0 | O10: 0 | P10: Cloth Tunic, Cloth Cap, Cloth Leggings, Cloth Shoes, Small Dagger, Wooden Buckler
A11: 8 | B11: Rogue | C11: 1 | D11: 12 | E11: 10 | F11: 0 | G11: 0 | H11: 0 | I11: 35 | J11: 0 | K11: 0 | L11: 0 | M11: 0 | N11: 0 | O11: 0 | P11: Cloth Tunic, Cloth Cap, Cloth Leggings, Cloth Shoes, Small Dagger, Wooden Buckler
A12: 9 | B12: Rogue | C12: 1 | D12: 12 | E12: 10 | F12: 0 | G12: 0 | H12: 0 | I12: 35 | J12: 0 | K12: 0 | L12: 0 | M12: 0 | N12: 0 | O12: 0 | P12: Cloth Tunic, Cloth Cap, Cloth Leggings, Cloth Shoes, Small Dagger, Wooden Buckler
A13: 10 | B13: Rogue | C13: 1 | D13: 12 | E13: 10 | F13: 0 | G13: 0 | H13: 0 | I13: 51 | J13: 0 | K13: 0 | L13: 0 | M13: 0 | N13: 0 | O13: 0 | P13: Leather Tunic, Leather Cap, Leather Leggings, Leather Boots, Small Dagger, Wooden Buckler
A14: 11 | B14: Rogue | C14: 1 | D14: 12 | E14: 10 | F14: 0 | G14: 0 | H14: 0 | I14: 51 | J14: 0 | K14: 0 | L14: 0 | M14: 0 | N14: 0 | O14: 0 | P14: Leather Tunic, Leather Cap, Leather Leggings, Leather Boots, Small Dagger, Wooden Buckler
A15: 12 | B15: Rogue | C15: 1 | D15: 12 | E15: 10 | F15: 0 | G15: 0 | H15: 0 | I15: 51 | J15: 0 | K15: 0 | L15: 0 | M15: 0 | N15: 0 | O15: 0 | P15: Leather Tunic, Leather Cap, Leather Leggings, Leather Boots, Small Dagger, Wooden Buckler
... A603: 50 | B603: Priest | C603: 3 | D603: 19 | E603: 10 | F603: 41 | G603: 3370 | H603: 2480 | I603: 375 | J603: 0.14 | K603: 0.1 | L603: 0.1 | M603: 0 | N603: 0.05 | O603: 0.05 | P603: Silk Tunic, Silk Cap, Silk Leggings, Silk Slippers, Brilliant Hammer, Firebrand Guard, Bulwark Belt, Exalted War Gloves, Skyweave Cloak, Charm of the Archon, Bulwark Pauldrons, Bracelet of the Inferno, Bracelet of the Inferno

Sheet Abilities
A1: Class ability tables
A2: Source: game data "Spells" + "Spell Effects" sheets and Scripts/Spell/Backstab.csx. Rows must stay sorted by learn level (LOOKUP picks the highest tier <= level).
A4: Backstab | G4: dmg = mult * (STR + weapon dmg + level) * (1+SD) * crit(SC); ignores AC; x1.5 from behind.
A5: Learn lvl | B5: Tier | C5: Multiplier | D5: Cooldown s | E5: MP cost
A6: 4 | B6: Backstab 1 | C6: 2 | D6: 15 | E6: 20
A7: 14 | B7: Backstab 2 | C7: 3.5 | D7: 15 | E7: 40
A8: 24 | B8: Backstab 3 | C8: 4.5 | D8: 15 | E8: 60
A9: 34 | B9: Backstab 4 | C9: 5.5 | D9: 15 | E9: 120
A10: 44 | B10: Backstab 5 | C10: 7.5 | D10: 15 | E10: 200
A12: Elemental Strike | N12: Flat damage * (1+SD) * crit(SC); ignores AC. Source: Spells / Spell Effects sheets. Shapes: SpellEffect.Cast. Pack coverage = share of the other pack mobs the shape catches (ES 5: Monte Carlo, ~2.6 of the 8 tiles around the target; ES 6/7: 4 of 8 neighbours; ES 8: line through the pack). Expected = 1 + pack share * (min(tiles, pack) - 1) * coverage. ES 8-10 are drops.
A13: Learn lvl | B13: Tier | C13: Damage | D13: Cooldown s | E13: MP cost | F13: Shape | G13: Tiles hit | H13: Pack coverage | I13: Max targets | J13: Expected targets | K13: Dmg per MP (1 target) | L13: Expected dmg per MP
A14: 1 | B14: ES 1 | C14: 15 | D14: 0.5 | E14: 5 | F14: Single | G14: 1 | H14: 0 | I14: =MIN(G14,Inputs!$C$14) | J14: =1+Inputs!$C$15*(MIN(G14,Inputs!$C$14)-1)*H14 | K14: =C14/E14 | L14: =C14*J14/E14
A15: 6 | B15: ES 2 | C15: 25 | D15: 0.5 | E15: 10 | F15: Single | G15: 1 | H15: 0 | I15: =MIN(G15,Inputs!$C$14) | J15: =1+Inputs!$C$15*(MIN(G15,Inputs!$C$14)-1)*H15 | K15: =C15/E15 | L15: =C15*J15/E15
A16: 11 | B16: ES 3 | C16: 45 | D16: 0.5 | E16: 20 | F16: Single | G16: 1 | H16: 0 | I16: =MIN(G16,Inputs!$C$14) | J16: =1+Inputs!$C$15*(MIN(G16,Inputs!$C$14)-1)*H16 | K16: =C16/E16 | L16: =C16*J16/E16
A17: 16 | B17: ES 4 | C17: 70 | D17: 0.5 | E17: 30 | F17: Single | G17: 1 | H17: 0 | I17: =MIN(G17,Inputs!$C$14) | J17: =1+Inputs!$C$15*(MIN(G17,Inputs!$C$14)-1)*H17 | K17: =C17/E17 | L17: =C17*J17/E17
A18: 21 | B18: ES 5 | C18: 100 | D18: 1 | E18: 65 | F18: Random 4 (33% spread) | G18: 81 | H18: 0.32 | I18: =MIN(G18,Inputs!$C$14) | J18: =1+Inputs!$C$15*(MIN(G18,Inputs!$C$14)-1)*H18 | K18: =C18/E18 | L18: =C18*J18/E18
A19: 26 | B19: ES 6 | C19: 130 | D19: 1 | E19: 110 | F19: Plus 1 | G19: 5 | H19: 0.5 | I19: =MIN(G19,Inputs!$C$14) | J19: =1+Inputs!$C$15*(MIN(G19,Inputs!$C$14)-1)*H19 | K19: =C19/E19 | L19: =C19*J19/E19
A20: 31 | B20: ES 7 | C20: 230 | D20: 1 | E20: 200 | F20: Cross 3 | G20: 13 | H20: 0.5 | I20: =MIN(G20,Inputs!$C$14) | J20: =1+Inputs!$C$15*(MIN(G20,Inputs!$C$14)-1)*H20 | K20: =C20/E20 | L20: =C20*J20/E20
A21: 36 | B21: ES 8 | C21: 280 | D21: 2 | E21: 220 | F21: Line 3 in front of caster | G21: 3 | H21: 0.25 | I21: =MIN(G21,Inputs!$C$14) | J21: =1+Inputs!$C$15*(MIN(G21,Inputs!$C$14)-1)*H21 | K21: =C21/E21 | L21: =C21*J21/E21
A22: 41 | B22: ES 9 | C22: 400 | D22: 0.8 | E22: 240 | F22: Single | G22: 1 | H22: 0 | I22: =MIN(G22,Inputs!$C$14) | J22: =1+Inputs!$C$15*(MIN(G22,Inputs!$C$14)-1)*H22 | K22: =C22/E22 | L22: =C22*J22/E22
A23: 46 | B23: ES 10 | C23: 500 | D23: 0.8 | E23: 280 | F23: Single | G23: 1 | H23: 0 | I23: =MIN(G23,Inputs!$C$14) | J23: =1+Inputs!$C$15*(MIN(G23,Inputs!$C$14)-1)*H23 | K23: =C23/E23 | L23: =C23*J23/E23
A25: Berserker | H25: Warrior self buff.
A26: Learn lvl | B26: Tier | C26: STR | D26: Haste | E26: Duration s | F26: Cooldown s
A27: 25 | B27: Berserker 1 | C27: 50 | D27: 0.1 | E27: 45 | F27: 230
A28: 35 | B28: Berserker 2 | C28: 100 | D28: 0.2 | E28: 60 | F28: 240
A29: 45 | B29: Berserker 3 | C29: 200 | D29: 0.3 | E29: 90 | F29: 280
A31: Chomp | L31: Warrior on-attack buff: every swing casts coef * (STR + weapon dmg + level) spell damage per target (proc chance defaults to 100%). Rage cannot be cast over Fury. Savage Fury is a plus centred on the warrior; the centre tile is the caster and is skipped (CanCastSpell), so it hits the 4 orthogonal neighbours. Coverage 50% = mobs surrounding a tank sit on 4 of the 8 neighbouring tiles.
A32: Learn lvl | B32: Tier | C32: Coefficient | D32: Duration s | E32: Cooldown s | F32: Shape | G32: Tiles hit | H32: Pack coverage | I32: Max targets | J32: Expected targets
A33: 5 | B33: Rampant Rage | C33: 1 | D33: 60 | E33: 140 | F33: Line 1 in front of warrior | G33: 1 | H33: 0 | I33: =MIN(G33,Inputs!$C$14) | J33: =1+Inputs!$C$15*(MIN(G33,Inputs!$C$14)-1)*H33
A34: 48 | B34: Savage Fury | C34: 2 | D34: 30 | E34: 200 | F34: Plus 1 around warrior | G34: 4 | H34: 0.5 | I34: =MIN(G34,Inputs!$C$14) | J34: =1+Inputs!$C$15*(MIN(G34,Inputs!$C$14)-1)*H34
A36: Nimble | H36: Rogue self buff. DEX only adds dodge (DEX/10000), so only haste is modelled.
A37: Learn lvl | B37: Tier | C37: DEX | D37: Haste | E37: Duration s | F37: Cooldown s
A38: 19 | B38: Nimble 1 | C38: 50 | D38: 0.1 | E38: 60 | F38: 90
A39: 29 | B39: Nimble 2 | C39: 75 | D39: 0.2 | E39: 60 | F39: 90
A40: 39 | B40: Nimble 3 | C40: 100 | D40: 0.3 | E40: 60 | F40: 90
A42: Poison | G42: Rogue on-attack buff applying a damage-over-time bubble; modelled as one bubble always ticking while the buff is up.
A43: Learn lvl | B43: Tier | C43: Tick dmg | D43: Duration s | E43: Cooldown s
A44: 11 | B44: Poison Weapon 1 | C44: 25 | D44: 60 | E44: 120
A45: 31 | B45: Poison Weapon 2 | C45: 50 | D45: 60 | E45: 120
A47: Strength | E47: Priest buff, 600s duration. Min-level-effected rules on the effect are ignored.
...

Sheet Mobs
A1: Spawned monsters, levels 1-49
A2: Source: game data "NPCs", "NPC Spawns", "Class Info" (HP/AC = template + class table row). Level-50 content runs on bought vita and is excluded.
A3: Name | B3: Level | C3: HP | D3: AC | E3: Class id | F3: AC mult | G3: Effective AC | H3: Base hit (STR+wdmg+lvl) | I3: Attack interval s | J3: Exp | K3: Spawns | L3: Respawn s | M3: Trash? | N3: Main map
A4: Mouse | B4: 1 | C4: 30 | D4: 0 | E4: 4 | F4: =IFERROR(INDEX('Class Table'!$O$4:$O$9,MATCH(E4,'Class Table'!$N$4:$N$9,0)),1) | G4: =D4*F4 | H4: 5 | I4: 1.5 | J4: 20 | K4: 28 | L4: 40 | M4: =IF(AND(L4<=Inputs!$C$9,K4>=Inputs!$C$10),1,0) | N4: Minita
A5: Lamb | B5: 2 | C5: 36 | D5: 0 | E5: 4 | F5: =IFERROR(INDEX('Class Table'!$O$4:$O$9,MATCH(E5,'Class Table'!$N$4:$N$9,0)),1) | G5: =D5*F5 | H5: 8 | I5: 1.5 | J5: 40 | K5: 27 | L5: 40 | M5: =IF(AND(L5<=Inputs!$C$9,K5>=Inputs!$C$10),1,0) | N5: Minita
A6: Fluffy Little Bunny | B6: 4 | C6: 57 | D6: 0 | E6: 4 | F6: =IFERROR(INDEX('Class Table'!$O$4:$O$9,MATCH(E6,'Class Table'!$N$4:$N$9,0)),1) | G6: =D6*F6 | H6: 13 | I6: 1.4 | J6: 104 | K6: 33 | L6: 30 | M6: =IF(AND(L6<=Inputs!$C$9,K6>=Inputs!$C$10),1,0) | N6: Arctic Lands
A7: The Big Cheese | B7: 5 | C7: 286 | D7: 0 | E7: 2 | F7: =IFERROR(INDEX('Class Table'!$O$4:$O$9,MATCH(E7,'Class Table'!$N$4:$N$9,0)),1) | G7: =D7*F7 | H7: 25 | I7: 1 | J7: 180 | K7: 1 | L7: 1800 | M7: =IF(AND(L7<=Inputs!$C$9,K7>=Inputs!$C$10),1,0) | N7: Minita
A8: Asp | B8: 6 | C8: 110 | D8: 0 | E8: 2 | F8: =IFERROR(INDEX('Class Table'!$O$4:$O$9,MATCH(E8,'Class Table'!$N$4:$N$9,0)),1) | G8: =D8*F8 | H8: 19 | I8: 1.4 | J8: 124 | K8: 57 | L8: 30 | M8: =IF(AND(L8<=Inputs!$C$9,K8>=Inputs!$C$10),1,0) | N8: Roadkill Woods
A9: Black Sheep | B9: 7 | C9: 442 | D9: 70 | E9: 3 | F9: =IFERROR(INDEX('Class Table'!$O$4:$O$9,MATCH(E9,'Class Table'!$N$4:$N$9,0)),1) | G9: =D9*F9 | H9: 32 | I9: 1 | J9: 220 | K9: 1 | L9: 1800 | M9: =IF(AND(L9<=Inputs!$C$9,K9>=Inputs!$C$10),1,0) | N9: Minita
A10: Coilfang | B10: 8 | C10: 445 | D10: 0 | E10: 2 | F10: =IFERROR(INDEX('Class Table'!$O$4:$O$9,MATCH(E10,'Class Table'!$N$4:$N$9,0)),1) | G10: =D10*F10 | H10: 32 | I10: 1 | J10: 230 | K10: 1 | L10: 1800 | M10: =IF(AND(L10<=Inputs!$C$9,K10>=Inputs!$C$10),1,0) | N10: Roadkill Woods
A11: Rabid Rabbit | B11: 8 | C11: 135 | D11: 0 | E11: 4 | F11: =IFERROR(INDEX('Class Table'!$O$4:$O$9,MATCH(E11,'Class Table'!$N$4:$N$9,0)),1) | G11: =D11*F11 | H11: 26 | I11: 1.4 | J11: 186 | K11: 59 | L11: 30 | M11: =IF(AND(L11<=Inputs!$C$9,K11>=Inputs!$C$10),1,0) | N11: Arctic Lands
A12: Cottontail | B12: 9 | C12: 206 | D12: 0 | E12: 2 | F12: =IFERROR(INDEX('Class Table'!$O$4:$O$9,MATCH(E12,'Class Table'!$N$4:$N$9,0)),1) | G12: =D12*F12 | H12: 37 | I12: 1.5 | J12: 250 | K12: 4 | L12: 1800 | M12: =IF(AND(L12<=Inputs!$C$9,K12>=Inputs!$C$10),1,0) | N12: Arctic Lands
A13: Bat | B13: 12 | C13: 338 | D13: 0 | E13: 2 | F13: =IFERROR(INDEX('Class Table'!$O$4:$O$9,MATCH(E13,'Class Table'!$N$4:$N$9,0)),1) | G13: =D13*F13 | H13: 50 | I13: 1.4 | J13: 266 | K13: 30 | L13: 30 | M13: =IF(AND(L13<=Inputs!$C$9,K13>=Inputs!$C$10),1,0) | N13: Its the Bat Cave Robin
A14: Green Slime | B14: 12 | C14: 492 | D14: 120 | E14: 3 | F14: =IFERROR(INDEX('Class Table'!$O$4:$O$9,MATCH(E14,'Class Table'!$N$4:$N$9,0)),1) | G14: =D14*F14 | H14: 60 | I14: 1.3 | J14: 246 | K14: 10 | L14: 30 | M14: =IF(AND(L14<=Inputs!$C$9,K14>=Inputs!$C$10),1,0) | N14: Slime Kingdom
A15: Lost Wabbit | B15: 12 | C15: 261 | D15: 0 | E15: 4 | F15: =IFERROR(INDEX('Class Table'!$O$4:$O$9,MATCH(E15,'Class Table'!$N$4:$N$9,0)),1) | G15: =D15*F15 | H15: 63 | I15: 1.3 | J15: 246 | K15: 114 | L15: 60 | M15: =IF(AND(L15<=Inputs!$C$9,K15>=Inputs!$C$10),1,0) | N15: Frigid Maze
... A74: Admiral Persecution | B74: 48 | C74: 11580 | D74: 480 | E74: 3 | F74: =IFERROR(INDEX('Class Table'!$O$4:$O$9,MATCH(E74,'Class Table'!$N$4:$N$9,0)),1) | G74: =D74*F74 | H74: 398 | I74: 1.4 | J74: 1500 | K74: 1 | L74: 1800 | M74: =IF(AND(L74<=Inputs!$C$9,K74>=Inputs!$C$10),1,0) | N74: Maroon Bay

Sheet Mob by Level
A1: Opponent per player level
A2: Typical = average of trash mobs within the level window (Inputs). Zero rows mean no trash mob near that level - widen the window.
A3: Player level | B3: Mob level | C3: Mob HP | D3: Mob effective AC | E3: Mob base hit | F3: Mob attack interval s | G3: Mob exp | H3: Mobs averaged
A4: 1 | B4: =IF(Inputs!$C$7<>"",INDEX(Mobs!$B$4:$B$74,MATCH(Inputs!$C$7,Mobs!$A$4:$A$74,0)),MIN(49,MAX(1,A4+Inputs!$C$6))) | C4: =IF(Inputs!$C$7<>"",INDEX(Mobs!$C$4:$C$74,MATCH(Inputs!$C$7,Mobs!$A$4:$A$74,0)),IFERROR(AVERAGEIFS(Mobs!$C$4:$C$74,Mobs!$B$4:$B$74,">="&(B4-Inputs!$C$8),Mobs!$B$4:$B$74,"<="&(B4+Inputs!$C$8),Mobs!$M$4:$M$74,1),0)) | D4: =IF(Inputs!$C$7<>"",INDEX(Mobs!$G$4:$G$74,MATCH(Inputs!$C$7,Mobs!$A$4:$A$74,0)),IFERROR(AVERAGEIFS(Mobs!$G$4:$G$74,Mobs!$B$4:$B$74,">="&(B4-Inputs!$C$8),Mobs!$B$4:$B$74,"<="&(B4+Inputs!$C$8),Mobs!$M$4:$M$74,1),0)) | E4: =IF(Inputs!$C$7<>"",INDEX(Mobs!$H$4:$H$74,MATCH(Inputs!$C$7,Mobs!$A$4:$A$74,0)),IFERROR(AVERAGEIFS(Mobs!$H$4:$H$74,Mobs!$B$4:$B$74,">="&(B4-Inputs!$C$8),Mobs!$B$4:$B$74,"<="&(B4+Inputs!$C$8),Mobs!$M$4:$M$74,1),0)) | F4: =IF(Inputs!$C$7<>"",INDEX(Mobs!$I$4:$I$74,MATCH(Inputs!$C$7,Mobs!$A$4:$A$74,0)),IFERROR(AVERAGEIFS(Mobs!$I$4:$I$74,Mobs!$B$4:$B$74,">="&(B4-Inputs!$C$8),Mobs!$B$4:$B$74,"<="&(B4+Inputs!$C$8),Mobs!$M$4:$M$74,1),0)) | G4: =IF(Inputs!$C$7<>"",INDEX(Mobs!$J$4:$J$74,MATCH(Inputs!$C$7,Mobs!$A$4:$A$74,0)),IFERROR(AVERAGEIFS(Mobs!$J$4:$J$74,Mobs!$B$4:$B$74,">="&(B4-Inputs!$C$8),Mobs!$B$4:$B$74,"<="&(B4+Inputs!$C$8),Mobs!$M$4:$M$74,1),0)) | H4: =IF(Inputs!$C$7<>"",1,COUNTIFS(Mobs!$B$4:$B$74,">="&(B4-Inputs!$C$8),Mobs!$B$4:$B$74,"<="&(B4+Inputs!$C$8),Mobs!$M$4:$M$74,1))
A5: 2 | B5: =IF(Inputs!$C$7<>"",INDEX(Mobs!$B$4:$B$74,MATCH(Inputs!$C$7,Mobs!$A$4:$A$74,0)),MIN(49,MAX(1,A5+Inputs!$C$6))) | C5: =IF(Inputs!$C$7<>"",INDEX(Mobs!$C$4:$C$74,MATCH(Inputs!$C$7,Mobs!$A$4:$A$74,0)),IFERROR(AVERAGEIFS(Mobs!$C$4:$C$74,Mobs!$B$4:$B$74,">="&(B5-Inputs!$C$8),Mobs!$B$4:$B$74,"<="&(B5+Inputs!$C$8),Mobs!$M$4:$M$74,1),0)) | D5: =IF(Inputs!$C$7<>"",INDEX(Mobs!$G$4:$G$74,MATCH(Inputs!$C$7,Mobs!$A$4:$A$74,0)),IFERROR(AVERAGEIFS(Mobs!$G$4:$G$74,Mobs!$B$4:$B$74,">="&(B5-Inputs!$C$8),Mobs!$B$4:$B$74,"<="&(B5+Inputs!$C$8),Mobs!$M$4:$M$74,1),0)) | E5: =IF(Inputs!$C$7<>"",INDEX(Mobs!$H$4:$H$74,MATCH(Inputs!$C$7,Mobs!$A$4:$A$74,0)),IFERROR(AVERAGEIFS(Mobs!$H$4:$H$74,Mobs!$B$4:$B$74,">="&(B5-Inputs!$C$8),Mobs!$B$4:$B$74,"<="&(B5+Inputs!$C$8),Mobs!$M$4:$M$74,1),0)) | F5: =IF(Inputs!$C$7<>"",INDEX(Mobs!$I$4:$I$74,MATCH(Inputs!$C$7,Mobs!$A$4:$A$74,0)),IFERROR(AVERAGEIFS(Mobs!$I$4:$I$74,Mobs!$B$4:$B$74,">="&(B5-Inputs!$C$8),Mobs!$B$4:$B$74,"<="&(B5+Inputs!$C$8),Mobs!$M$4:$M$74,1),0)) | G5: =IF(Inputs!$C$7<>"",INDEX(Mobs!$J$4:$J$74,MATCH(Inputs!$C$7,Mobs!$A$4:$A$74,0)),IFERROR(AVERAGEIFS(Mobs!$J$4:$J$74,Mobs!$B$4:$B$74,">="&(B5-Inputs!$C$8),Mobs!$B$4:$B$74,"<="&(B5+Inputs!$C$8),Mobs!$M$4:$M$74,1),0)) | H5: =IF(Inputs!$C$7<>"",1,COUNTIFS(Mobs!$B$4:$B$74,">="&(B5-Inputs!$C$8),Mobs!$B$4:$B$74,"<="&(B5+Inputs!$C$8),Mobs!$M$4:$M$74,1))
A6: 3 | B6: =IF(Inputs!$C$7<>"",INDEX(Mobs!$B$4:$B$74,MATCH(Inputs!$C$7,Mobs!$A$4:$A$74,0)),MIN(49,MAX(1,A6+Inputs!$C$6))) | C6: =IF(Inputs!$C$7<>"",INDEX(Mobs!$C$4:$C$74,MATCH(Inputs!$C$7,Mobs!$A$4:$A$74,0)),IFERROR(AVERAGEIFS(Mobs!$C$4:$C$74,Mobs!$B$4:$B$74,">="&(B6-Inputs!$C$8),Mobs!$B$4:$B$74,"<="&(B6+Inputs!$C$8),Mobs!$M$4:$M$74,1),0)) | D6: =IF(Inputs!$C$7<>"",INDEX(Mobs!$G$4:$G$74,MATCH(Inputs!$C$7,Mobs!$A$4:$A$74,0)),IFERROR(AVERAGEIFS(Mobs!$G$4:$G$74,Mobs!$B$4:$B$74,">="&(B6-Inputs!$C$8),Mobs!$B$4:$B$74,"<="&(B6+Inputs!$C$8),Mobs!$M$4:$M$74,1),0)) | E6: =IF(Inputs!$C$7<>"",INDEX(Mobs!$H$4:$H$74,MATCH(Inputs!$C$7,Mobs!$A$4:$A$74,0)),IFERROR(AVERAGEIFS(Mobs!$H$4:$H$74,Mobs!$B$4:$B$74,">="&(B6-Inputs!$C$8),Mobs!$B$4:$B$74,"<="&(B6+Inputs!$C$8),Mobs!$M$4:$M$74,1),0)) | F6: =IF(Inputs!$C$7<>"",INDEX(Mobs!$I$4:$I$74,MATCH(Inputs!$C$7,Mobs!$A$4:$A$74,0)),IFERROR(AVERAGEIFS(Mobs!$I$4:$I$74,Mobs!$B$4:$B$74,">="&(B6-Inputs!$C$8),Mobs!$B$4:$B$74,"<="&(B6+Inputs!$C$8),Mobs!$M$4:$M$74,1),0)) | G6: =IF(Inputs!$C$7<>"",INDEX(Mobs!$J$4:$J$74,MATCH(Inputs!$C$7,Mobs!$A$4:$A$74,0)),IFERROR(AVERAGEIFS(Mobs!$J$4:$J$74,Mobs!$B$4:$B$74,">="&(B6-Inputs!$C$8),Mobs!$B$4:$B$74,"<="&(B6+Inputs!$C$8),Mobs!$M$4:$M$74,1),0)) | H6: =IF(Inputs!$C$7<>"",1,COUNTIFS(Mobs!$B$4:$B$74,">="&(B6-Inputs!$C$8),Mobs!$B$4:$B$74,"<="&(B6+Inputs!$C$8),Mobs!$M$4:$M$74,1))
A7: 4 | B7: =IF(Inputs!$C$7<>"",INDEX(Mobs!$B$4:$B$74,MATCH(Inputs!$C$7,Mobs!$A$4:$A$74,0)),MIN(49,MAX(1,A7+Inputs!$C$6))) | C7: =IF(Inputs!$C$7<>"",INDEX(Mobs!$C$4:$C$74,MATCH(Inputs!$C$7,Mobs!$A$4:$A$74,0)),IFERROR(AVERAGEIFS(Mobs!$C$4:$C$74,Mobs!$B$4:$B$74,">="&(B7-Inputs!$C$8),Mobs!$B$4:$B$74,"<="&(B7+Inputs!$C$8),Mobs!$M$4:$M$74,1),0)) | D7: =IF(Inputs!$C$7<>"",INDEX(Mobs!$G$4:$G$74,MATCH(Inputs!$C$7,Mobs!$A$4:$A$74,0)),IFERROR(AVERAGEIFS(Mobs!$G$4:$G$74,Mobs!$B$4:$B$74,">="&(B7-Inputs!$C$8),Mobs!$B$4:$B$74,"<="&(B7+Inputs!$C$8),Mobs!$M$4:$M$74,1),0)) | E7: =IF(Inputs!$C$7<>"",INDEX(Mobs!$H$4:$H$74,MATCH(Inputs!$C$7,Mobs!$A$4:$A$74,0)),IFERROR(AVERAGEIFS(Mobs!$H$4:$H$74,Mobs!$B$4:$B$74,">="&(B7-Inputs!$C$8),Mobs!$B$4:$B$74,"<="&(B7+Inputs!$C$8),Mobs!$M$4:$M$74,1),0)) | F7: =IF(Inputs!$C$7<>"",INDEX(Mobs!$I$4:$I$74,MATCH(Inputs!$C$7,Mobs!$A$4:$A$74,0)),IFERROR(AVERAGEIFS(Mobs!$I$4:$I$74,Mobs!$B$4:$B$74,">="&(B7-Inputs!$C$8),Mobs!$B$4:$B$74,"<="&(B7+Inputs!$C$8),Mobs!$M$4:$M$74,1),0)) | G7: =IF(Inputs!$C$7<>"",INDEX(Mobs!$J$4:$J$74,MATCH(Inputs!$C$7,Mobs!$A$4:$A$74,0)),IFERROR(AVERAGEIFS(Mobs!$J$4:$J$74,Mobs!$B$4:$B$74,">="&(B7-Inputs!$C$8),Mobs!$B$4:$B$74,"<="&(B7+Inputs!$C$8),Mobs!$M$4:$M$74,1),0)) | H7: =IF(Inputs!$C$7<>"",1,COUNTIFS(Mobs!$B$4:$B$74,">="&(B7-Inputs!$C$8),Mobs!$B$4:$B$74,"<="&(B7+Inputs!$C$8),Mobs!$M$4:$M$74,1))
A8: 5 | B8: =IF(Inputs!$C$7<>"",INDEX(Mobs!$B$4:$B$74,MATCH(Inputs!$C$7,Mobs!$A$4:$A$74,0)),MIN(49,MAX(1,A8+Inputs!$C$6))) | C8: =IF(Inputs!$C$7<>"",INDEX(Mobs!$C$4:$C$74,MATCH(Inputs!$C$7,Mobs!$A$4:$A$74,0)),IFERROR(AVERAGEIFS(Mobs!$C$4:$C$74,Mobs!$B$4:$B$74,">="&(B8-Inputs!$C$8),Mobs!$B$4:$B$74,"<="&(B8+Inputs!$C$8),Mobs!$M$4:$M$74,1),0)) | D8: =IF(Inputs!$C$7<>"",INDEX(Mobs!$G$4:$G$74,MATCH(Inputs!$C$7,Mobs!$A$4:$A$74,0)),IFERROR(AVERAGEIFS(Mobs!$G$4:$G$74,Mobs!$B$4:$B$74,">="&(B8-Inputs!$C$8),Mobs!$B$4:$B$74,"<="&(B8+Inputs!$C$8),Mobs!$M$4:$M$74,1),0)) | E8: =IF(Inputs!$C$7<>"",INDEX(Mobs!$H$4:$H$74,MATCH(Inputs!$C$7,Mobs!$A$4:$A$74,0)),IFERROR(AVERAGEIFS(Mobs!$H$4:$H$74,Mobs!$B$4:$B$74,">="&(B8-Inputs!$C$8),Mobs!$B$4:$B$74,"<="&(B8+Inputs!$C$8),Mobs!$M$4:$M$74,1),0)) | F8: =IF(Inputs!$C$7<>"",INDEX(Mobs!$I$4:$I$74,MATCH(Inputs!$C$7,Mobs!$A$4:$A$74,0)),IFERROR(AVERAGEIFS(Mobs!$I$4:$I$74,Mobs!$B$4:$B$74,">="&(B8-Inputs!$C$8),Mobs!$B$4:$B$74,"<="&(B8+Inputs!$C$8),Mobs!$M$4:$M$74,1),0)) | G8: =IF(Inputs!$C$7<>"",INDEX(Mobs!$J$4:$J$74,MATCH(Inputs!$C$7,Mobs!$A$4:$A$74,0)),IFERROR(AVERAGEIFS(Mobs!$J$4:$J$74,Mobs!$B$4:$B$74,">="&(B8-Inputs!$C$8),Mobs!$B$4:$B$74,"<="&(B8+Inputs!$C$8),Mobs!$M$4:$M$74,1),0)) | H8: =IF(Inputs!$C$7<>"",1,COUNTIFS(Mobs!$B$4:$B$74,">="&(B8-Inputs!$C$8),Mobs!$B$4:$B$74,"<="&(B8+Inputs!$C$8),Mobs!$M$4:$M$74,1))
A9: 6 | B9: =IF(Inputs!$C$7<>"",INDEX(Mobs!$B$4:$B$74,MATCH(Inputs!$C$7,Mobs!$A$4:$A$74,0)),MIN(49,MAX(1,A9+Inputs!$C$6))) | C9: =IF(Inputs!$C$7<>"",INDEX(Mobs!$C$4:$C$74,MATCH(Inputs!$C$7,Mobs!$A$4:$A$74,0)),IFERROR(AVERAGEIFS(Mobs!$C$4:$C$74,Mobs!$B$4:$B$74,">="&(B9-Inputs!$C$8),Mobs!$B$4:$B$74,"<="&(B9+Inputs!$C$8),Mobs!$M$4:$M$74,1),0)) | D9: =IF(Inputs!$C$7<>"",INDEX(Mobs!$G$4:$G$74,MATCH(Inputs!$C$7,Mobs!$A$4:$A$74,0)),IFERROR(AVERAGEIFS(Mobs!$G$4:$G$74,Mobs!$B$4:$B$74,">="&(B9-Inputs!$C$8),Mobs!$B$4:$B$74,"<="&(B9+Inputs!$C$8),Mobs!$M$4:$M$74,1),0)) | E9: =IF(Inputs!$C$7<>"",INDEX(Mobs!$H$4:$H$74,MATCH(Inputs!$C$7,Mobs!$A$4:$A$74,0)),IFERROR(AVERAGEIFS(Mobs!$H$4:$H$74,Mobs!$B$4:$B$74,">="&(B9-Inputs!$C$8),Mobs!$B$4:$B$74,"<="&(B9+Inputs!$C$8),Mobs!$M$4:$M$74,1),0)) | F9: =IF(Inputs!$C$7<>"",INDEX(Mobs!$I$4:$I$74,MATCH(Inputs!$C$7,Mobs!$A$4:$A$74,0)),IFERROR(AVERAGEIFS(Mobs!$I$4:$I$74,Mobs!$B$4:$B$74,">="&(B9-Inputs!$C$8),Mobs!$B$4:$B$74,"<="&(B9+Inputs!$C$8),Mobs!$M$4:$M$74,1),0)) | G9: =IF(Inputs!$C$7<>"",INDEX(Mobs!$J$4:$J$74,MATCH(Inputs!$C$7,Mobs!$A$4:$A$74,0)),IFERROR(AVERAGEIFS(Mobs!$J$4:$J$74,Mobs!$B$4:$B$74,">="&(B9-Inputs!$C$8),Mobs!$B$4:$B$74,"<="&(B9+Inputs!$C$8),Mobs!$M$4:$M$74,1),0)) | H9: =IF(Inputs!$C$7<>"",1,COUNTIFS(Mobs!$B$4:$B$74,">="&(B9-Inputs!$C$8),Mobs!$B$4:$B$74,"<="&(B9+Inputs!$C$8),Mobs!$M$4:$M$74,1))
A10: 7 | B10: =IF(Inputs!$C$7<>"",INDEX(Mobs!$B$4:$B$74,MATCH(Inputs!$C$7,Mobs!$A$4:$A$74,0)),MIN(49,MAX(1,A10+Inputs!$C$6))) | C10: =IF(Inputs!$C$7<>"",INDEX(Mobs!$C$4:$C$74,MATCH(Inputs!$C$7,Mobs!$A$4:$A$74,0)),IFERROR(AVERAGEIFS(Mobs!$C$4:$C$74,Mobs!$B$4:$B$74,">="&(B10-Inputs!$C$8),Mobs!$B$4:$B$74,"<="&(B10+Inputs!$C$8),Mobs!$M$4:$M$74,1),0)) | D10: =IF(Inputs!$C$7<>"",INDEX(Mobs!$G$4:$G$74,MATCH(Inputs!$C$7,Mobs!$A$4:$A$74,0)),IFERROR(AVERAGEIFS(Mobs!$G$4:$G$74,Mobs!$B$4:$B$74,">="&(B10-Inputs!$C$8),Mobs!$B$4:$B$74,"<="&(B10+Inputs!$C$8),Mobs!$M$4:$M$74,1),0)) | E10: =IF(Inputs!$C$7<>"",INDEX(Mobs!$H$4:$H$74,MATCH(Inputs!$C$7,Mobs!$A$4:$A$74,0)),IFERROR(AVERAGEIFS(Mobs!$H$4:$H$74,Mobs!$B$4:$B$74,">="&(B10-Inputs!$C$8),Mobs!$B$4:$B$74,"<="&(B10+Inputs!$C$8),Mobs!$M$4:$M$74,1),0)) | F10: =IF(Inputs!$C$7<>"",INDEX(Mobs!$I$4:$I$74,MATCH(Inputs!$C$7,Mobs!$A$4:$A$74,0)),IFERROR(AVERAGEIFS(Mobs!$I$4:$I$74,Mobs!$B$4:$B$74,">="&(B10-Inputs!$C$8),Mobs!$B$4:$B$74,"<="&(B10+Inputs!$C$8),Mobs!$M$4:$M$74,1),0)) | G10: =IF(Inputs!$C$7<>"",INDEX(Mobs!$J$4:$J$74,MATCH(Inputs!$C$7,Mobs!$A$4:$A$74,0)),IFERROR(AVERAGEIFS(Mobs!$J$4:$J$74,Mobs!$B$4:$B$74,">="&(B10-Inputs!$C$8),Mobs!$B$4:$B$74,"<="&(B10+Inputs!$C$8),Mobs!$M$4:$M$74,1),0)) | H10: =IF(Inputs!$C$7<>"",1,COUNTIFS(Mobs!$B$4:$B$74,">="&(B10-Inputs!$C$8),Mobs!$B$4:$B$74,"<="&(B10+Inputs!$C$8),Mobs!$M$4:$M$74,1))
A11: 8 | B11: =IF(Inputs!$C$7<>"",INDEX(Mobs!$B$4:$B$74,MATCH(Inputs!$C$7,Mobs!$A$4:$A$74,0)),MIN(49,MAX(1,A11+Inputs!$C$6))) | C11: =IF(Inputs!$C$7<>"",INDEX(Mobs!$C$4:$C$74,MATCH(Inputs!$C$7,Mobs!$A$4:$A$74,0)),IFERROR(AVERAGEIFS(Mobs!$C$4:$C$74,Mobs!$B$4:$B$74,">="&(B11-Inputs!$C$8),Mobs!$B$4:$B$74,"<="&(B11+Inputs!$C$8),Mobs!$M$4:$M$74,1),0)) | D11: =IF(Inputs!$C$7<>"",INDEX(Mobs!$G$4:$G$74,MATCH(Inputs!$C$7,Mobs!$A$4:$A$74,0)),IFERROR(AVERAGEIFS(Mobs!$G$4:$G$74,Mobs!$B$4:$B$74,">="&(B11-Inputs!$C$8),Mobs!$B$4:$B$74,"<="&(B11+Inputs!$C$8),Mobs!$M$4:$M$74,1),0)) | E11: =IF(Inputs!$C$7<>"",INDEX(Mobs!$H$4:$H$74,MATCH(Inputs!$C$7,Mobs!$A$4:$A$74,0)),IFERROR(AVERAGEIFS(Mobs!$H$4:$H$74,Mobs!$B$4:$B$74,">="&(B11-Inputs!$C$8),Mobs!$B$4:$B$74,"<="&(B11+Inputs!$C$8),Mobs!$M$4:$M$74,1),0)) | F11: =IF(Inputs!$C$7<>"",INDEX(Mobs!$I$4:$I$74,MATCH(Inputs!$C$7,Mobs!$A$4:$A$74,0)),IFERROR(AVERAGEIFS(Mobs!$I$4:$I$74,Mobs!$B$4:$B$74,">="&(B11-Inputs!$C$8),Mobs!$B$4:$B$74,"<="&(B11+Inputs!$C$8),Mobs!$M$4:$M$74,1),0)) | G11: =IF(Inputs!$C$7<>"",INDEX(Mobs!$J$4:$J$74,MATCH(Inputs!$C$7,Mobs!$A$4:$A$74,0)),IFERROR(AVERAGEIFS(Mobs!$J$4:$J$74,Mobs!$B$4:$B$74,">="&(B11-Inputs!$C$8),Mobs!$B$4:$B$74,"<="&(B11+Inputs!$C$8),Mobs!$M$4:$M$74,1),0)) | H11: =IF(Inputs!$C$7<>"",1,COUNTIFS(Mobs!$B$4:$B$74,">="&(B11-Inputs!$C$8),Mobs!$B$4:$B$74,"<="&(B11+Inputs!$C$8),Mobs!$M$4:$M$74,1))
A12: 9 | B12: =IF(Inputs!$C$7<>"",INDEX(Mobs!$B$4:$B$74,MATCH(Inputs!$C$7,Mobs!$A$4:$A$74,0)),MIN(49,MAX(1,A12+Inputs!$C$6))) | C12: =IF(Inputs!$C$7<>"",INDEX(Mobs!$C$4:$C$74,MATCH(Inputs!$C$7,Mobs!$A$4:$A$74,0)),IFERROR(AVERAGEIFS(Mobs!$C$4:$C$74,Mobs!$B$4:$B$74,">="&(B12-Inputs!$C$8),Mobs!$B$4:$B$74,"<="&(B12+Inputs!$C$8),Mobs!$M$4:$M$74,1),0)) | D12: =IF(Inputs!$C$7<>"",INDEX(Mobs!$G$4:$G$74,MATCH(Inputs!$C$7,Mobs!$A$4:$A$74,0)),IFERROR(AVERAGEIFS(Mobs!$G$4:$G$74,Mobs!$B$4:$B$74,">="&(B12-Inputs!$C$8),Mobs!$B$4:$B$74,"<="&(B12+Inputs!$C$8),Mobs!$M$4:$M$74,1),0)) | E12: =IF(Inputs!$C$7<>"",INDEX(Mobs!$H$4:$H$74,MATCH(Inputs!$C$7,Mobs!$A$4:$A$74,0)),IFERROR(AVERAGEIFS(Mobs!$H$4:$H$74,Mobs!$B$4:$B$74,">="&(B12-Inputs!$C$8),Mobs!$B$4:$B$74,"<="&(B12+Inputs!$C$8),Mobs!$M$4:$M$74,1),0)) | F12: =IF(Inputs!$C$7<>"",INDEX(Mobs!$I$4:$I$74,MATCH(Inputs!$C$7,Mobs!$A$4:$A$74,0)),IFERROR(AVERAGEIFS(Mobs!$I$4:$I$74,Mobs!$B$4:$B$74,">="&(B12-Inputs!$C$8),Mobs!$B$4:$B$74,"<="&(B12+Inputs!$C$8),Mobs!$M$4:$M$74,1),0)) | G12: =IF(Inputs!$C$7<>"",INDEX(Mobs!$J$4:$J$74,MATCH(Inputs!$C$7,Mobs!$A$4:$A$74,0)),IFERROR(AVERAGEIFS(Mobs!$J$4:$J$74,Mobs!$B$4:$B$74,">="&(B12-Inputs!$C$8),Mobs!$B$4:$B$74,"<="&(B12+Inputs!$C$8),Mobs!$M$4:$M$74,1),0)) | H12: =IF(Inputs!$C$7<>"",1,COUNTIFS(Mobs!$B$4:$B$74,">="&(B12-Inputs!$C$8),Mobs!$B$4:$B$74,"<="&(B12+Inputs!$C$8),Mobs!$M$4:$M$74,1))
A13: 10 | B13: =IF(Inputs!$C$7<>"",INDEX(Mobs!$B$4:$B$74,MATCH(Inputs!$C$7,Mobs!$A$4:$A$74,0)),MIN(49,MAX(1,A13+Inputs!$C$6))) | C13: =IF(Inputs!$C$7<>"",INDEX(Mobs!$C$4:$C$74,MATCH(Inputs!$C$7,Mobs!$A$4:$A$74,0)),IFERROR(AVERAGEIFS(Mobs!$C$4:$C$74,Mobs!$B$4:$B$74,">="&(B13-Inputs!$C$8),Mobs!$B$4:$B$74,"<="&(B13+Inputs!$C$8),Mobs!$M$4:$M$74,1),0)) | D13: =IF(Inputs!$C$7<>"",INDEX(Mobs!$G$4:$G$74,MATCH(Inputs!$C$7,Mobs!$A$4:$A$74,0)),IFERROR(AVERAGEIFS(Mobs!$G$4:$G$74,Mobs!$B$4:$B$74,">="&(B13-Inputs!$C$8),Mobs!$B$4:$B$74,"<="&(B13+Inputs!$C$8),Mobs!$M$4:$M$74,1),0)) | E13: =IF(Inputs!$C$7<>"",INDEX(Mobs!$H$4:$H$74,MATCH(Inputs!$C$7,Mobs!$A$4:$A$74,0)),IFERROR(AVERAGEIFS(Mobs!$H$4:$H$74,Mobs!$B$4:$B$74,">="&(B13-Inputs!$C$8),Mobs!$B$4:$B$74,"<="&(B13+Inputs!$C$8),Mobs!$M$4:$M$74,1),0)) | F13: =IF(Inputs!$C$7<>"",INDEX(Mobs!$I$4:$I$74,MATCH(Inputs!$C$7,Mobs!$A$4:$A$74,0)),IFERROR(AVERAGEIFS(Mobs!$I$4:$I$74,Mobs!$B$4:$B$74,">="&(B13-Inputs!$C$8),Mobs!$B$4:$B$74,"<="&(B13+Inputs!$C$8),Mobs!$M$4:$M$74,1),0)) | G13: =IF(Inputs!$C$7<>"",INDEX(Mobs!$J$4:$J$74,MATCH(Inputs!$C$7,Mobs!$A$4:$A$74,0)),IFERROR(AVERAGEIFS(Mobs!$J$4:$J$74,Mobs!$B$4:$B$74,">="&(B13-Inputs!$C$8),Mobs!$B$4:$B$74,"<="&(B13+Inputs!$C$8),Mobs!$M$4:$M$74,1),0)) | H13: =IF(Inputs!$C$7<>"",1,COUNTIFS(Mobs!$B$4:$B$74,">="&(B13-Inputs!$C$8),Mobs!$B$4:$B$74,"<="&(B13+Inputs!$C$8),Mobs!$M$4:$M$74,1))
A14: 11 | B14: =IF(Inputs!$C$7<>"",INDEX(Mobs!$B$4:$B$74,MATCH(Inputs!$C$7,Mobs!$A$4:$A$74,0)),MIN(49,MAX(1,A14+Inputs!$C$6))) | C14: =IF(Inputs!$C$7<>"",INDEX(Mobs!$C$4:$C$74,MATCH(Inputs!$C$7,Mobs!$A$4:$A$74,0)),IFERROR(AVERAGEIFS(Mobs!$C$4:$C$74,Mobs!$B$4:$B$74,">="&(B14-Inputs!$C$8),Mobs!$B$4:$B$74,"<="&(B14+Inputs!$C$8),Mobs!$M$4:$M$74,1),0)) | D14: =IF(Inputs!$C$7<>"",INDEX(Mobs!$G$4:$G$74,MATCH(Inputs!$C$7,Mobs!$A$4:$A$74,0)),IFERROR(AVERAGEIFS(Mobs!$G$4:$G$74,Mobs!$B$4:$B$74,">="&(B14-Inputs!$C$8),Mobs!$B$4:$B$74,"<="&(B14+Inputs!$C$8),Mobs!$M$4:$M$74,1),0)) | E14: =IF(Inputs!$C$7<>"",INDEX(Mobs!$H$4:$H$74,MATCH(Inputs!$C$7,Mobs!$A$4:$A$74,0)),IFERROR(AVERAGEIFS(Mobs!$H$4:$H$74,Mobs!$B$4:$B$74,">="&(B14-Inputs!$C$8),Mobs!$B$4:$B$74,"<="&(B14+Inputs!$C$8),Mobs!$M$4:$M$74,1),0)) | F14: =IF(Inputs!$C$7<>"",INDEX(Mobs!$I$4:$I$74,MATCH(Inputs!$C$7,Mobs!$A$4:$A$74,0)),IFERROR(AVERAGEIFS(Mobs!$I$4:$I$74,Mobs!$B$4:$B$74,">="&(B14-Inputs!$C$8),Mobs!$B$4:$B$74,"<="&(B14+Inputs!$C$8),Mobs!$M$4:$M$74,1),0)) | G14: =IF(Inputs!$C$7<>"",INDEX(Mobs!$J$4:$J$74,MATCH(Inputs!$C$7,Mobs!$A$4:$A$74,0)),IFERROR(AVERAGEIFS(Mobs!$J$4:$J$74,Mobs!$B$4:$B$74,">="&(B14-Inputs!$C$8),Mobs!$B$4:$B$74,"<="&(B14+Inputs!$C$8),Mobs!$M$4:$M$74,1),0)) | H14: =IF(Inputs!$C$7<>"",1,COUNTIFS(Mobs!$B$4:$B$74,">="&(B14-Inputs!$C$8),Mobs!$B$4:$B$74,"<="&(B14+Inputs!$C$8),Mobs!$M$4:$M$74,1))
A15: 12 | B15: =IF(Inputs!$C$7<>"",INDEX(Mobs!$B$4:$B$74,MATCH(Inputs!$C$7,Mobs!$A$4:$A$74,0)),MIN(49,MAX(1,A15+Inputs!$C$6))) | C15: =IF(Inputs!$C$7<>"",INDEX(Mobs!$C$4:$C$74,MATCH(Inputs!$C$7,Mobs!$A$4:$A$74,0)),IFERROR(AVERAGEIFS(Mobs!$C$4:$C$74,Mobs!$B$4:$B$74,">="&(B15-Inputs!$C$8),Mobs!$B$4:$B$74,"<="&(B15+Inputs!$C$8),Mobs!$M$4:$M$74,1),0)) | D15: =IF(Inputs!$C$7<>"",INDEX(Mobs!$G$4:$G$74,MATCH(Inputs!$C$7,Mobs!$A$4:$A$74,0)),IFERROR(AVERAGEIFS(Mobs!$G$4:$G$74,Mobs!$B$4:$B$74,">="&(B15-Inputs!$C$8),Mobs!$B$4:$B$74,"<="&(B15+Inputs!$C$8),Mobs!$M$4:$M$74,1),0)) | E15: =IF(Inputs!$C$7<>"",INDEX(Mobs!$H$4:$H$74,MATCH(Inputs!$C$7,Mobs!$A$4:$A$74,0)),IFERROR(AVERAGEIFS(Mobs!$H$4:$H$74,Mobs!$B$4:$B$74,">="&(B15-Inputs!$C$8),Mobs!$B$4:$B$74,"<="&(B15+Inputs!$C$8),Mobs!$M$4:$M$74,1),0)) | F15: =IF(Inputs!$C$7<>"",INDEX(Mobs!$I$4:$I$74,MATCH(Inputs!$C$7,Mobs!$A$4:$A$74,0)),IFERROR(AVERAGEIFS(Mobs!$I$4:$I$74,Mobs!$B$4:$B$74,">="&(B15-Inputs!$C$8),Mobs!$B$4:$B$74,"<="&(B15+Inputs!$C$8),Mobs!$M$4:$M$74,1),0)) | G15: =IF(Inputs!$C$7<>"",INDEX(Mobs!$J$4:$J$74,MATCH(Inputs!$C$7,Mobs!$A$4:$A$74,0)),IFERROR(AVERAGEIFS(Mobs!$J$4:$J$74,Mobs!$B$4:$B$74,">="&(B15-Inputs!$C$8),Mobs!$B$4:$B$74,"<="&(B15+Inputs!$C$8),Mobs!$M$4:$M$74,1),0)) | H15: =IF(Inputs!$C$7<>"",1,COUNTIFS(Mobs!$B$4:$B$74,">="&(B15-Inputs!$C$8),Mobs!$B$4:$B$74,"<="&(B15+Inputs!$C$8),Mobs!$M$4:$M$74,1))
... A52: 49 | B52: =IF(Inputs!$C$7<>"",INDEX(Mobs!$B$4:$B$74,MATCH(Inputs!$C$7,Mobs!$A$4:$A$74,0)),MIN(49,MAX(1,A52+Inputs!$C$6))) | C52: =IF(Inputs!$C$7<>"",INDEX(Mobs!$C$4:$C$74,MATCH(Inputs!$C$7,Mobs!$A$4:$A$74,0)),IFERROR(AVERAGEIFS(Mobs!$C$4:$C$74,Mobs!$B$4:$B$74,">="&(B52-Inputs!$C$8),Mobs!$B$4:$B$74,"<="&(B52+Inputs!$C$8),Mobs!$M$4:$M$74,1),0)) | D52: =IF(Inputs!$C$7<>"",INDEX(Mobs!$G$4:$G$74,MATCH(Inputs!$C$7,Mobs!$A$4:$A$74,0)),IFERROR(AVERAGEIFS(Mobs!$G$4:$G$74,Mobs!$B$4:$B$74,">="&(B52-Inputs!$C$8),Mobs!$B$4:$B$74,"<="&(B52+Inputs!$C$8),Mobs!$M$4:$M$74,1),0)) | E52: =IF(Inputs!$C$7<>"",INDEX(Mobs!$H$4:$H$74,MATCH(Inputs!$C$7,Mobs!$A$4:$A$74,0)),IFERROR(AVERAGEIFS(Mobs!$H$4:$H$74,Mobs!$B$4:$B$74,">="&(B52-Inputs!$C$8),Mobs!$B$4:$B$74,"<="&(B52+Inputs!$C$8),Mobs!$M$4:$M$74,1),0)) | F52: =IF(Inputs!$C$7<>"",INDEX(Mobs!$I$4:$I$74,MATCH(Inputs!$C$7,Mobs!$A$4:$A$74,0)),IFERROR(AVERAGEIFS(Mobs!$I$4:$I$74,Mobs!$B$4:$B$74,">="&(B52-Inputs!$C$8),Mobs!$B$4:$B$74,"<="&(B52+Inputs!$C$8),Mobs!$M$4:$M$74,1),0)) | G52: =IF(Inputs!$C$7<>"",INDEX(Mobs!$J$4:$J$74,MATCH(Inputs!$C$7,Mobs!$A$4:$A$74,0)),IFERROR(AVERAGEIFS(Mobs!$J$4:$J$74,Mobs!$B$4:$B$74,">="&(B52-Inputs!$C$8),Mobs!$B$4:$B$74,"<="&(B52+Inputs!$C$8),Mobs!$M$4:$M$74,1),0)) | H52: =IF(Inputs!$C$7<>"",1,COUNTIFS(Mobs!$B$4:$B$74,">="&(B52-Inputs!$C$8),Mobs!$B$4:$B$74,"<="&(B52+Inputs!$C$8),Mobs!$M$4:$M$74,1))

Sheet Warrior
A1: Warrior - expected damage by level
A2: Melee + Rampant Rage / Savage Fury chomps + Berserker, averaged by uptime. | B2: Opponent | G2: Gear / class | S2: Melee (no cooldowns) | W2: Berserker | AD2: Rampant Rage / Savage Fury | AK2: Result | AO2: Survival
A3: Level | B3: Mob level | C3: Mob HP | D3: Mob eff. AC | E3: Mob base hit | F3: Mob atk s | G3: Weapon dmg | H3: Weapon delay | I3: STR (gear + priest buff) | J3: Spell dmg % | K3: Spell crit % | L3: Melee dmg % | M3: Melee crit % | N3: Haste % | O3: Player max HP | P3: Player max MP | Q3: Player AC | R3: Dmg reduce % | S3: Raw melee hit | T3: Melee hit vs mob | U3: Swing s | V3: Melee DPS | W3: Berserker STR | X3: Berserker haste | Y3: Berserker uptime | Z3: Raw melee hit (berserk) | AA3: Melee hit vs mob (berserk) | AB3: Swing s (berserk) | AC3: Melee DPS (berserk) | AD3: Rage uptime | AE3: Fury uptime | AF3: Rage targets per chomp | AG3: Fury targets per chomp | AH3: Avg chomp coef x targets / swing | AI3: Chomp dmg / swing | AJ3: Chomp dmg / swing (berserk) | AK3: SUSTAINED DPS | AL3: Burst DPS (all buffs up) | AM3: Chomp share of dmg | AN3: Swings to kill (melee only) | AO3: Time to kill s | AP3: Mob hit on player | AQ3: Dmg taken per kill | AR3: % HP lost per kill | AS3: HP regen per kill | AT3: Net % HP per kill (after regen)
A4: 1 | B4: ='Mob by Level'!B4 | C4: ='Mob by Level'!C4 | D4: ='Mob by Level'!D4 | E4: ='Mob by Level'!E4 | F4: ='Mob by Level'!F4 | G4: =SUMIFS(Gear!$D$4:$D$603,Gear!$A$4:$A$603,A4,Gear!$B$4:$B$603,"Warrior",Gear!$C$4:$C$603,Inputs!$C$5) | H4: =SUMIFS(Gear!$E$4:$E$603,Gear!$A$4:$A$603,A4,Gear!$B$4:$B$603,"Warrior",Gear!$C$4:$C$603,Inputs!$C$5) | I4: =SUMIFS(Gear!$F$4:$F$603,Gear!$A$4:$A$603,A4,Gear!$B$4:$B$603,"Warrior",Gear!$C$4:$C$603,Inputs!$C$5)+Inputs!$C$17*IFERROR(LOOKUP(A4,Abilities!$A$49:$A$53,Abilities!$C$49:$C$53),0) | J4: =SUMIFS(Gear!$J$4:$J$603,Gear!$A$4:$A$603,A4,Gear!$B$4:$B$603,"Warrior",Gear!$C$4:$C$603,Inputs!$C$5) | K4: =SUMIFS(Gear!$K$4:$K$603,Gear!$A$4:$A$603,A4,Gear!$B$4:$B$603,"Warrior",Gear!$C$4:$C$603,Inputs!$C$5) | L4: =SUMIFS(Gear!$L$4:$L$603,Gear!$A$4:$A$603,A4,Gear!$B$4:$B$603,"Warrior",Gear!$C$4:$C$603,Inputs!$C$5) | M4: =SUMIFS(Gear!$M$4:$M$603,Gear!$A$4:$A$603,A4,Gear!$B$4:$B$603,"Warrior",Gear!$C$4:$C$603,Inputs!$C$5) | N4: =SUMIFS(Gear!$N$4:$N$603,Gear!$A$4:$A$603,A4,Gear!$B$4:$B$603,"Warrior",Gear!$C$4:$C$603,Inputs!$C$5) | O4: =INDEX('Class Table'!$E$4:$E$53,A4)+SUMIFS(Gear!$G$4:$G$603,Gear!$A$4:$A$603,A4,Gear!$B$4:$B$603,"Warrior",Gear!$C$4:$C$603,Inputs!$C$5) | P4: =INDEX('Class Table'!$F$4:$F$53,A4)+SUMIFS(Gear!$H$4:$H$603,Gear!$A$4:$A$603,A4,Gear!$B$4:$B$603,"Warrior",Gear!$C$4:$C$603,Inputs!$C$5) | Q4: =INDEX('Class Table'!$G$4:$G$53,A4)+SUMIFS(Gear!$I$4:$I$603,Gear!$A$4:$A$603,A4,Gear!$B$4:$B$603,"Warrior",Gear!$C$4:$C$603,Inputs!$C$5) | R4: =SUMIFS(Gear!$O$4:$O$603,Gear!$A$4:$A$603,A4,Gear!$B$4:$B$603,"Warrior",Gear!$C$4:$C$603,Inputs!$C$5) | S4: =I4+0+G4+A4+MAX(1,A4/2)+(A4-B4) | T4: =MAX(0,S4*(1+M4)*(1+L4)*Inputs!$C$20*(1-D4/Inputs!$C$19)-D4/25) | U4: =H4/10*(1-MIN(0.95,N4+0))*Inputs!$C$21 | V4: =T4/U4 | W4: =IFERROR(LOOKUP(A4,Abilities!$A$27:$A$29,Abilities!$C$27:$C$29),0) | X4: =IFERROR(LOOKUP(A4,Abilities!$A$27:$A$29,Abilities!$D$27:$D$29),0) | Y4: =Inputs!$C$16*IFERROR(LOOKUP(A4,Abilities!$A$27:$A$29,Abilities!$E$27:$E$29),0)/IFERROR(LOOKUP(A4,Abilities!$A$27:$A$29,Abilities!$F$27:$F$29),1) | Z4: =I4+W4+G4+A4+MAX(1,A4/2)+(A4-B4) | AA4: =MAX(0,Z4*(1+M4)*(1+L4)*Inputs!$C$20*(1-D4/Inputs!$C$19)-D4/25) | AB4: =H4/10*(1-MIN(0.95,N4+X4))*Inputs!$C$21 | AC4: =AA4/AB4 | AD4: =Inputs!$C$16*IF(A4>=INDEX(Abilities!$A$33:$A$34,1),INDEX(Abilities!$D$33:$D$34,1)/INDEX(Abilities!$E$33:$E$34,1),0) | AE4: =Inputs!$C$16*IF(A4>=INDEX(Abilities!$A$33:$A$34,2),INDEX(Abilities!$D$33:$D$34,2)/INDEX(Abilities!$E$33:$E$34,2),0) | AF4: =CHOOSE(Inputs!$C$13,1,INDEX(Abilities!$J$33:$J$34,1),INDEX(Abilities!$I$33:$I$34,1)) | AG4: =CHOOSE(Inputs!$C$13,1,INDEX(Abilities!$J$33:$J$34,2),INDEX(Abilities!$I$33:$I$34,2)) | AH4: =INDEX(Abilities!$C$33:$C$34,2)*AG4*AE4+INDEX(Abilities!$C$33:$C$34,1)*AF4*MIN(AD4,1-AE4) | AI4: =AH4*(I4+G4+A4)*(1+J4)*(1+K4)*Inputs!$C$20 | AJ4: =AH4*(I4+W4+G4+A4)*(1+J4)*(1+K4)*Inputs!$C$20 | AK4: =(1-Y4)*(T4+AI4)/U4+Y4*(AA4+AJ4)/AB4 | AL4: =(AA4+IF(A4>=INDEX(Abilities!$A$33:$A$34,2),INDEX(Abilities!$C$33:$C$34,2)*AG4,IF(A4>=INDEX(Abilities!$A$33:$A$34,1),INDEX(Abilities!$C$33:$C$34,1)*AF4,0))*(I4+W4+G4+A4)*(1+J4)*(1+K4)*Inputs!$C$20)/AB4 | AM4: =IFERROR(((1-Y4)*AI4/U4+Y4*AJ4/AB4)/AK4,0) | AN4: =IFERROR(ROUNDUP(C4/T4,0),"-") | AO4: =IFERROR(C4/AK4,"-") | AP4: =MAX(0,(E4+(B4-A4))*(1-R4)*(1-Q4*'Class Table'!$O$6/Inputs!$C$19)-Q4*'Class Table'!$O$6/25) | AQ4: =IFERROR(AP4/F4*AO4,"-") | AR4: =IFERROR(AQ4/O4,"-") | AS4: =IFERROR(O4*Inputs!$C$24/Inputs!$C$22*AO4,"-") | AT4: =IFERROR(MAX(0,AQ4-AS4)/O4,"-")
A5: 2 | B5: ='Mob by Level'!B5 | C5: ='Mob by Level'!C5 | D5: ='Mob by Level'!D5 | E5: ='Mob by Level'!E5 | F5: ='Mob by Level'!F5 | G5: =SUMIFS(Gear!$D$4:$D$603,Gear!$A$4:$A$603,A5,Gear!$B$4:$B$603,"Warrior",Gear!$C$4:$C$603,Inputs!$C$5) | H5: =SUMIFS(Gear!$E$4:$E$603,Gear!$A$4:$A$603,A5,Gear!$B$4:$B$603,"Warrior",Gear!$C$4:$C$603,Inputs!$C$5) | I5: =SUMIFS(Gear!$F$4:$F$603,Gear!$A$4:$A$603,A5,Gear!$B$4:$B$603,"Warrior",Gear!$C$4:$C$603,Inputs!$C$5)+Inputs!$C$17*IFERROR(LOOKUP(A5,Abilities!$A$49:$A$53,Abilities!$C$49:$C$53),0) | J5: =SUMIFS(Gear!$J$4:$J$603,Gear!$A$4:$A$603,A5,Gear!$B$4:$B$603,"Warrior",Gear!$C$4:$C$603,Inputs!$C$5) | K5: =SUMIFS(Gear!$K$4:$K$603,Gear!$A$4:$A$603,A5,Gear!$B$4:$B$603,"Warrior",Gear!$C$4:$C$603,Inputs!$C$5) | L5: =SUMIFS(Gear!$L$4:$L$603,Gear!$A$4:$A$603,A5,Gear!$B$4:$B$603,"Warrior",Gear!$C$4:$C$603,Inputs!$C$5) | M5: =SUMIFS(Gear!$M$4:$M$603,Gear!$A$4:$A$603,A5,Gear!$B$4:$B$603,"Warrior",Gear!$C$4:$C$603,Inputs!$C$5) | N5: =SUMIFS(Gear!$N$4:$N$603,Gear!$A$4:$A$603,A5,Gear!$B$4:$B$603,"Warrior",Gear!$C$4:$C$603,Inputs!$C$5) | O5: =INDEX('Class Table'!$E$4:$E$53,A5)+SUMIFS(Gear!$G$4:$G$603,Gear!$A$4:$A$603,A5,Gear!$B$4:$B$603,"Warrior",Gear!$C$4:$C$603,Inputs!$C$5) | P5: =INDEX('Class Table'!$F$4:$F$53,A5)+SUMIFS(Gear!$H$4:$H$603,Gear!$A$4:$A$603,A5,Gear!$B$4:$B$603,"Warrior",Gear!$C$4:$C$603,Inputs!$C$5) | Q5: =INDEX('Class Table'!$G$4:$G$53,A5)+SUMIFS(Gear!$I$4:$I$603,Gear!$A$4:$A$603,A5,Gear!$B$4:$B$603,"Warrior",Gear!$C$4:$C$603,Inputs!$C$5) | R5: =SUMIFS(Gear!$O$4:$O$603,Gear!$A$4:$A$603,A5,Gear!$B$4:$B$603,"Warrior",Gear!$C$4:$C$603,Inputs!$C$5) | S5: =I5+0+G5+A5+MAX(1,A5/2)+(A5-B5) | T5: =MAX(0,S5*(1+M5)*(1+L5)*Inputs!$C$20*(1-D5/Inputs!$C$19)-D5/25) | U5: =H5/10*(1-MIN(0.95,N5+0))*Inputs!$C$21 | V5: =T5/U5 | W5: =IFERROR(LOOKUP(A5,Abilities!$A$27:$A$29,Abilities!$C$27:$C$29),0) | X5: =IFERROR(LOOKUP(A5,Abilities!$A$27:$A$29,Abilities!$D$27:$D$29),0) | Y5: =Inputs!$C$16*IFERROR(LOOKUP(A5,Abilities!$A$27:$A$29,Abilities!$E$27:$E$29),0)/IFERROR(LOOKUP(A5,Abilities!$A$27:$A$29,Abilities!$F$27:$F$29),1) | Z5: =I5+W5+G5+A5+MAX(1,A5/2)+(A5-B5) | AA5: =MAX(0,Z5*(1+M5)*(1+L5)*Inputs!$C$20*(1-D5/Inputs!$C$19)-D5/25) | AB5: =H5/10*(1-MIN(0.95,N5+X5))*Inputs!$C$21 | AC5: =AA5/AB5 | AD5: =Inputs!$C$16*IF(A5>=INDEX(Abilities!$A$33:$A$34,1),INDEX(Abilities!$D$33:$D$34,1)/INDEX(Abilities!$E$33:$E$34,1),0) | AE5: =Inputs!$C$16*IF(A5>=INDEX(Abilities!$A$33:$A$34,2),INDEX(Abilities!$D$33:$D$34,2)/INDEX(Abilities!$E$33:$E$34,2),0) | AF5: =CHOOSE(Inputs!$C$13,1,INDEX(Abilities!$J$33:$J$34,1),INDEX(Abilities!$I$33:$I$34,1)) | AG5: =CHOOSE(Inputs!$C$13,1,INDEX(Abilities!$J$33:$J$34,2),INDEX(Abilities!$I$33:$I$34,2)) | AH5: =INDEX(Abilities!$C$33:$C$34,2)*AG5*AE5+INDEX(Abilities!$C$33:$C$34,1)*AF5*MIN(AD5,1-AE5) | AI5: =AH5*(I5+G5+A5)*(1+J5)*(1+K5)*Inputs!$C$20 | AJ5: =AH5*(I5+W5+G5+A5)*(1+J5)*(1+K5)*Inputs!$C$20 | AK5: =(1-Y5)*(T5+AI5)/U5+Y5*(AA5+AJ5)/AB5 | AL5: =(AA5+IF(A5>=INDEX(Abilities!$A$33:$A$34,2),INDEX(Abilities!$C$33:$C$34,2)*AG5,IF(A5>=INDEX(Abilities!$A$33:$A$34,1),INDEX(Abilities!$C$33:$C$34,1)*AF5,0))*(I5+W5+G5+A5)*(1+J5)*(1+K5)*Inputs!$C$20)/AB5 | AM5: =IFERROR(((1-Y5)*AI5/U5+Y5*AJ5/AB5)/AK5,0) | AN5: =IFERROR(ROUNDUP(C5/T5,0),"-") | AO5: =IFERROR(C5/AK5,"-") | AP5: =MAX(0,(E5+(B5-A5))*(1-R5)*(1-Q5*'Class Table'!$O$6/Inputs!$C$19)-Q5*'Class Table'!$O$6/25) | AQ5: =IFERROR(AP5/F5*AO5,"-") | AR5: =IFERROR(AQ5/O5,"-") | AS5: =IFERROR(O5*Inputs!$C$24/Inputs!$C$22*AO5,"-") | AT5: =IFERROR(MAX(0,AQ5-AS5)/O5,"-")
